Workbook

Sheet Sheet4
A1: idsbr | B1: nama | C1: kode_kbli | D1: kategori_kbli | E1: kegiatan_profiling | F1: kepemilikan_usaha | G1: badan_hukum | H1: jaringan_usaha | I1: sektor_institusi | J1: sumber_profiling | K1: catatan_profiling
A2: 32138612 | B2: Azizah | C2: 01111 | D2: A | E2: Pertanian Jagung | F2: 2 | G2: =IF(J2=Master!$F$2,"12.", "1.") -> 12. | I2: =IF(J2=Master!$F$2,"S14 - ", "S12 - ") -> S14 - | J2: OSS - Perorangan | K2: Status mengikuti sebelumnya (aktif)
A3: 29484151 | B3: Tahiyah | C3: 25112 | D3: C | E3: Industri Barang Dari Logam Aluminium Siap Pasang Untuk Bangunan | F3: 2 | G3: =IF(J3=Master!$F$2,"12.", "1.") -> 12. | I3: =IF(J3=Master!$F$2,"S14 - ", "S12 - ") -> S14 - | J3: OSS - Perorangan | K3: Status mengikuti sebelumnya (aktif)
A4: 30624837 | B4: Maya yunita sari | C4: 79129 | D4: N | E4: Aktivitas Biro Perjalanan Lainnya | F4: 2 | G4: =IF(J4=Master!$F$2,"12.", "1.") -> 12. | I4: =IF(J4=Master!$F$2,"S14 - ", "S12 - ") -> S14 - | J4: OSS - Perorangan | K4: Status mengikuti sebelumnya (aktif)
A5: 30763693 | B5: SUMINAH | C5: 56103 | D5: I | E5: Kedai Makanan | F5: 2 | G5: =IF(J5=Master!$F$2,"12.", "1.") -> 12. | I5: =IF(J5=Master!$F$2,"S14 - ", "S12 - ") -> S14 - | J5: OSS - Perorangan | K5: Status mengikuti sebelumnya (aktif)
A6: 30876943 | B6: TATIK CINTIA | C6: 47772 | D6: G | E6: Perdagangan Eceran Gas Elpiji | F6: 2 | G6: =IF(J6=Master!$F$2,"12.", "1.") -> 12. | I6: =IF(J6=Master!$F$2,"S14 - ", "S12 - ") -> S14 - | J6: OSS - Perorangan | K6: Status mengikuti sebelumnya (aktif)
A7: 31779556 | B7: ENDRA WIJAYA | C7: 77100 | D7: N | E7: Aktivitas Penyewaan dan Sewa Guna Usaha Tanpa Hak Opsi Mobil, Bus, Truk Dan Sejenisnya | F7: 2 | G7: =IF(J7=Master!$F$2,"12.", "1.") -> 12. | I7: =IF(J7=Master!$F$2,"S14 - ", "S12 - ") -> S14 - | J7: OSS - Perorangan | K7: Status mengikuti sebelumnya (aktif)
A8: 27120451 | B8: ZENA AZALIA | C8: 82110 | D8: N | E8: Aktivitas Penyedia Gabungan Jasa Administrasi Kantor | F8: 2 | G8: =IF(J8=Master!$F$2,"12.", "1.") -> 12. | I8: =IF(J8=Master!$F$2,"S14 - ", "S12 - ") -> S14 - | J8: OSS - Perorangan | K8: Status mengikuti sebelumnya (aktif)
A9: 28742046 | B9: WIDI YANIS | C9: 86105 | D9: Q | E9: Aktivitas Klinik Swasta | F9: 2 | G9: =IF(J9=Master!$F$2,"12.", "1.") -> 12. | I9: =IF(J9=Master!$F$2,"S14 - ", "S12 - ") -> S14 - | J9: OSS - Perorangan | K9: Status mengikuti sebelumnya (aktif)
A10: 28075247 | B10: PANCA MENARDO SIMANJUNTAK | C10: 96111 | D10: S | E10: Aktivitas Pangkas Rambut | F10: 2 | G10: =IF(J10=Master!$F$2,"12.", "1.") -> 12. | I10: =IF(J10=Master!$F$2,"S14 - ", "S12 - ") -> S14 - | J10: OSS - Perorangan | K10: Status mengikuti sebelumnya (aktif)
A11: 26121930 | B11: NOVIA ERLINDA | C11: 56102 | D11: I | E11: Rumah/Warung Makan | F11: 2 | G11: =IF(J11=Master!$F$2,"12.", "1.") -> 12. | I11: =IF(J11=Master!$F$2,"S14 - ", "S12 - ") -> S14 - | J11: OSS - Perorangan | K11: Status mengikuti sebelumnya (aktif)
A12: 27097673 | B12: SRI NURAINI | C12: 56304 | D12: I | E12: Kedai Minuman | F12: 2 | G12: =IF(J12=Master!$F$2,"12.", "1.") -> 12. | I12: =IF(J12=Master!$F$2,"S14 - ", "S12 - ") -> S14 - | J12: OSS - Perorangan | K12: Status mengikuti sebelumnya (aktif)
A13: 32176038 | B13: SEMIWATI | C13: 10794 | D13: C | E13: Industri Kerupuk, Keripik, Peyek Dan Sejenisnya | F13: 2 | G13: =IF(J13=Master!$F$2,"12.", "1.") -> 12. | I13: =IF(J13=Master!$F$2,"S14 - ", "S12 - ") -> S14 - | J13: OSS - Perorangan | K13: Status mengikuti sebelumnya (aktif)
... A1157: 29404335 | B1157: Lasmiati | C1157: 01135 | D1157: A | E1157: Pertanian Aneka Umbi Palawija | F1157: 2 | G1157: =IF(J1157=Master!$F$2,"12.", "1.") -> 12. | I1157: =IF(J1157=Master!$F$2,"S14 - ", "S12 - ") -> S14 - | J1157: OSS - Perorangan | K1157: Status mengikuti sebelumnya (aktif)
A1158: 31565231 | B1158: HAMDANI | C1158: 10740 | D1158: C | F1158: 2 | G1158: =IF(J1158=Master!$F$2,"12.", "1.") -> 12. | I1158: =IF(J1158=Master!$F$2,"S14 - ", "S12 - ") -> S14 - | J1158: OSS - Perorangan | K1158: Status mengikuti sebelumnya (aktif)
A1159: 32141498 | B1159: Rosma br hutabarat | C1159: 46696 | D1159: G | E1159: Perdagangan Besar Barang Bekas Dan Sisa-sisa Tak Terpakai (Scrap) | F1159: 2 | G1159: =IF(J1159=Master!$F$2,"12.", "1.") -> 12. | I1159: =IF(J1159=Master!$F$2,"S14 - ", "S12 - ") -> S14 - | J1159: OSS - Perorangan | K1159: Status mengikuti sebelumnya (aktif)
A1160: 29199124 | B1160: PENI NURIKA | C1160: 47112 | D1160: G | E1160: Perdagangan Eceran Berbagai Macam Barang Yang Utamanya Makanan, Minuman Atau Tembakau Bukan Di Minimarket/Supermarket/Hypermarket (Tradisional) | F1160: 2 | G1160: =IF(J1160=Master!$F$2,"12.", "1.") -> 12. | I1160: =IF(J1160=Master!$F$2,"S14 - ", "S12 - ") -> S14 - | J1160: OSS - Perorangan | K1160: Status mengikuti sebelumnya (aktif)
A1161: 31333584 | B1161: NENI MARLINA | C1161: 56102 | D1161: I | E1161: Rumah/Warung Makan | F1161: 2 | G1161: =IF(J1161=Master!$F$2,"12.", "1.") -> 12. | I1161: =IF(J1161=Master!$F$2,"S14 - ", "S12 - ") -> S14 - | J1161: OSS - Perorangan | K1161: Status mengikuti sebelumnya (aktif)
A1162: 27959809 | B1162: SRI HANDAYANI | C1162: 10794 | D1162: C | E1162: Industri Kerupuk, Keripik, Peyek Dan Sejenisnya | F1162: 2 | G1162: =IF(J1162=Master!$F$2,"12.", "1.") -> 12. | I1162: =IF(J1162=Master!$F$2,"S14 - ", "S12 - ") -> S14 - | J1162: OSS - Perorangan | K1162: Status mengikuti sebelumnya (aktif)
A1163: 29746254 | B1163: WIWIT SYUFRATMAL | C1163: 56304 | D1163: I | E1163: Kedai Minuman | F1163: 2 | G1163: =IF(J1163=Master!$F$2,"12.", "1.") -> 12. | I1163: =IF(J1163=Master!$F$2,"S14 - ", "S12 - ") -> S14 - | J1163: OSS - Perorangan | K1163: Status mengikuti sebelumnya (aktif)
A1164: 30591320 | B1164: Asnawati | C1164: 22292 | D1164: C | E1164: Industri Perlengkapan Dan Peralatan Rumah Tangga (tidak Termasuk Furnitur) | F1164: 2 | G1164: =IF(J1164=Master!$F$2,"12.", "1.") -> 12. | I1164: =IF(J1164=Master!$F$2,"S14 - ", "S12 - ") -> S14 - | J1164: OSS - Perorangan | K1164: Status mengikuti sebelumnya (aktif)
A1165: 29952697 | B1165: SYAHRIA | C1165: 56103 | D1165: I | E1165: Kedai Makanan | F1165: 2 | G1165: =IF(J1165=Master!$F$2,"12.", "1.") -> 12. | I1165: =IF(J1165=Master!$F$2,"S14 - ", "S12 - ") -> S14 - | J1165: OSS - Perorangan | K1165: Status mengikuti sebelumnya (aktif)
A1166: 26305257 | B1166: BERLI ATI SIR | C1166: 01468 | D1166: A | E1166: Pembibitan Ayam Ras | F1166: 2 | G1166: =IF(J1166=Master!$F$2,"12.", "1.") -> 12. | I1166: =IF(J1166=Master!$F$2,"S14 - ", "S12 - ") -> S14 - | J1166: OSS - Perorangan | K1166: Status mengikuti sebelumnya (aktif)
A1167: 32364450 | B1167: Jusama | C1167: 01261 | D1167: A | E1167: Perkebunan Buah Kelapa | F1167: 2 | G1167: =IF(J1167=Master!$F$2,"12.", "1.") -> 12. | I1167: =IF(J1167=Master!$F$2,"S14 - ", "S12 - ") -> S14 - | J1167: OSS - Perorangan | K1167: Status mengikuti sebelumnya (aktif)
A1168: 25830483 | B1168: MUJIBUL QARIM | C1168: 47112 | D1168: G | E1168: Perdagangan Eceran Berbagai Macam Barang Yang Utamanya Makanan, Minuman Atau Tembakau Bukan Di Minimarket/Supermarket/Hypermarket (Tradisional) | F1168: 2 | G1168: =IF(J1168=Master!$F$2,"12.", "1.") -> 12. | I1168: =IF(J1168=Master!$F$2,"S14 - ", "S12 - ") -> S14 - | J1168: OSS - Perorangan | K1168: Status mengikuti sebelumnya (aktif)
A1169: 29301621 | B1169: RAITAH | C1169: 10722 | D1169: C | E1169: Industri Gula Merah | F1169: 2 | G1169: =IF(J1169=Master!$F$2,"12.", "1.") -> 12. | I1169: =IF(J1169=Master!$F$2,"S14 - ", "S12 - ") -> S14 - | J1169: OSS - Perorangan | K1169: Status mengikuti sebelumnya (aktif)
A1170: 26595708 | B1170: ADINDA INTAN SAWITRI | C1170: 56103 | D1170: I | E1170: Kedai Makanan | F1170: 2 | G1170: =IF(J1170=Master!$F$2,"12.", "1.") -> 12. | I1170: =IF(J1170=Master!$F$2,"S14 - ", "S12 - ") -> S14 - | J1170: OSS - Perorangan | K1170: Status mengikuti sebelumnya (aktif)
... A1439: 32365263 | B1439: NAJWA | C1439: 56103 | D1439: I | E1439: Kedai Makanan | F1439: 2 | G1439: =IF(J1439=Master!$F$2,"12.", "1.") -> 12. | I1439: =IF(J1439=Master!$F$2,"S14 - ", "S12 - ") -> S14 - | J1439: OSS - Perorangan | K1439: Status mengikuti sebelumnya (aktif)
A1440: 26049931 | B1440: DWI FITRIANTI | C1440: 10740 | D1440: C | F1440: 2 | G1440: =IF(J1440=Master!$F$2,"12.", "1.") -> 12. | I1440: =IF(J1440=Master!$F$2,"S14 - ", "S12 - ") -> S14 - | J1440: OSS - Perorangan | K1440: Status mengikuti sebelumnya (aktif)
A1441: 26353009 | B1441: ALJUFRI | C1441: 56305 | D1441: I | E1441: Rumah/Kedai Obat Tradisional | F1441: 2 | G1441: =IF(J1441=Master!$F$2,"12.", "1.") -> 12. | I1441: =IF(J1441=Master!$F$2,"S14 - ", "S12 - ") -> S14 - | J1441: OSS - Perorangan | K1441: Status mengikuti sebelumnya (aktif)
A1442: 26368540 | B1442: SATRIA PAMUNGKAS | C1442: 47761 | D1442: G | E1442: Perdagangan Eceran Bunga Potong/Florist | F1442: 2 | G1442: =IF(J1442=Master!$F$2,"12.", "1.") -> 12. | I1442: =IF(J1442=Master!$F$2,"S14 - ", "S12 - ") -> S14 - | J1442: OSS - Perorangan | K1442: Status mengikuti sebelumnya (aktif)
A1443: 32212564 | B1443: Maskana | C1443: 10799 | D1443: C | E1443: Industri Produk Makanan Lainnya | F1443: 2 | G1443: =IF(J1443=Master!$F$2,"12.", "1.") -> 12. | I1443: =IF(J1443=Master!$F$2,"S14 - ", "S12 - ") -> S14 - | J1443: OSS - Perorangan | K1443: Status mengikuti sebelumnya (aktif)
A1444: 32274814 | B1444: FITRI AKBAR | C1444: 10710 | D1444: C | E1444: Industri Produk Roti Dan Kue | F1444: 2 | G1444: =IF(J1444=Master!$F$2,"12.", "1.") -> 12. | I1444: =IF(J1444=Master!$F$2,"S14 - ", "S12 - ") -> S14 - | J1444: OSS - Perorangan | K1444: Status mengikuti sebelumnya (aktif)
A1445: 31033307 | B1445: SAROH JUNIARTI | C1445: 47763 | D1445: G | E1445: Perdagangan Eceran Pupuk Dan Pemberantas Hama | F1445: 2 | G1445: =IF(J1445=Master!$F$2,"12.", "1.") -> 12. | I1445: =IF(J1445=Master!$F$2,"S14 - ", "S12 - ") -> S14 - | J1445: OSS - Perorangan | K1445: Status mengikuti sebelumnya (aktif)
A1446: 31151131 | B1446: SYAHRUL ROBY | C1446: 10794 | D1446: C | E1446: Industri Kerupuk, Keripik, Peyek Dan Sejenisnya | F1446: 2 | G1446: =IF(J1446=Master!$F$2,"12.", "1.") -> 12. | I1446: =IF(J1446=Master!$F$2,"S14 - ", "S12 - ") -> S14 - | J1446: OSS - Perorangan | K1446: Status mengikuti sebelumnya (aktif)
A1447: 26442224 | B1447: MARADONGAN TAMBUNAN | C1447: 56103 | D1447: I | E1447: Kedai Makanan | F1447: 2 | G1447: =IF(J1447=Master!$F$2,"12.", "1.") -> 12. | I1447: =IF(J1447=Master!$F$2,"S14 - ", "S12 - ") -> S14 - | J1447: OSS - Perorangan | K1447: Status mengikuti sebelumnya (aktif)
A1448: 32137282 | B1448: Anita | C1448: 10799 | D1448: C | E1448: Industri Produk Makanan Lainnya | F1448: 2 | G1448: =IF(J1448=Master!$F$2,"12.", "1.") -> 12. | I1448: =IF(J1448=Master!$F$2,"S14 - ", "S12 - ") -> S14 - | J1448: OSS - Perorangan | K1448: Status mengikuti sebelumnya (aktif)
A1449: 27687887 | B1449: SRI MULYATI | C1449: 47230 | D1449: G | E1449: Perdagangan Eceran Khusus Rokok dan Tembakau di Toko | F1449: 2 | G1449: =IF(J1449=Master!$F$2,"12.", "1.") -> 12. | I1449: =IF(J1449=Master!$F$2,"S14 - ", "S12 - ") -> S14 - | J1449: OSS - Perorangan | K1449: Status mengikuti sebelumnya (aktif)
A1450: 28805877 | B1450: CYNTHIA RIZKA RIANI | C1450: 10531 | D1450: C | E1450: Industri Pengolahan Es Krim | F1450: 2 | G1450: =IF(J1450=Master!$F$2,"12.", "1.") -> 12. | I1450: =IF(J1450=Master!$F$2,"S14 - ", "S12 - ") -> S14 - | J1450: OSS - Perorangan | K1450: Status mengikuti sebelumnya (aktif)
A1451: 29478636 | B1451: RIKA ELIANA | C1451: 11090 | D1451: C | E1451: Industri Minuman Lainnya | F1451: 2 | G1451: =IF(J1451=Master!$F$2,"12.", "1.") -> 12. | I1451: =IF(J1451=Master!$F$2,"S14 - ", "S12 - ") -> S14 - | J1451: OSS - Perorangan | K1451: Status mengikuti sebelumnya (aktif)
...

Sheet Master
A1: IDSBR | B1: Nama Usaha | C1: Status Perusahaan | D1: Kegiatan Usaha | E1: Skala Usaha | F1: Sumber Data | G1: kode_kbli | H1: kategori_kbli | I1: kegiatan_profiling | J1: Kecamatan | K1: Kelurahan/Desa
A2: 32183718 | B2: Misna | C2: Aktif | D2: [Kegiatan Usaha: -, Kategori: -, KBLI: 10799] | E2: UNDEFINED | F2: OSS - Perorangan | G2: {=IFERROR( _xlfn.TEXTJOIN(", ", TRUE, TEXT(TRIM(_xlfn.TEXTAFTER( _xlfn.TEXTBEFORE( _xlfn.FILTERXML("<t><s>" & SUBSTITUTE(D2, ";", "</s><s>") & "</s></t>", "//s"), "]" ), "KBLI:" )), "00000") ), "")} -> 10799 | H2: {=IF(G2="","", _xlfn.TEXTJOIN(", ",TRUE, _xlfn.UNIQUE( _xlfn.MAP( _xlfn.TEXTSPLIT(G2,","),_xlfn.LAMBDA(_xlpm.k, _xlfn.LET( _xlpm.kode,TRIM(TEXT(_xlpm.k,"00000")), _xlpm.d,--LEFT(_xlpm.kode,2), IF(AND(_xlpm.d>=1,_xlpm.d<=3),"A", IF(AND(_xlpm.d>=5,_xlpm.d<=9),"B", IF(AND(_xlpm.d>=10,_xlpm.d<=33),"C", IF(_xlpm.d=35,"D", IF(AND(_xlpm.d>=36,_xlpm.d<=39),"E", IF(AND(_xlpm.d>=41,_xlpm.d<=43),"F", IF(AND(_xlpm.d>=45,_xlpm.d<=47),"G", IF(AND(_xlpm.d>=49,_xlpm.d<=53),"H", IF(AND(_xlpm.d>=55,_xlpm.d<=56),"I", IF(AND(_xlpm.d>=58,_xlpm.d<=63),"J", IF(AND(_xlpm.d>=64,_xlpm.d<=66),"K", IF(_xlpm.d=68,"L", IF(AND(_xlpm.d>=69,_xlpm.d<=75),"M", IF(AND(_xlpm.d>=77,_xlpm.d<=82),"N", IF(_xlpm.d=84,"O", IF(_xlpm.d=85,"P", IF(AND(_xlpm.d>=86,_xlpm.d<=88),"Q", IF(AND(_xlpm.d>=90,_xlpm.d<=93),"R", IF(AND(_xlpm.d>=94,_xlpm.d<=96),"S", IF(AND(_xlpm.d>=97,_xlpm.d<=98),"T", IF(_xlpm.d=99,"U","Tidak diketahui"))))))))))))))))))))) ) ) ) ) ))} -> C | I2: {=_xlfn.LET( _xlpm.isi, G2, IF(_xlpm.isi="","", _xlfn.LET( _xlpm.daftar, _xlfn.TEXTSPLIT(_xlpm.isi, ","), _xlpm.bersih, TRIM(_xlpm.daftar), _xlpm.hasil, _xlfn.MAP(_xlpm.bersih, _xlfn.LAMBDA(_xlpm.k, IFERROR( _xlfn.XLOOKUP( TRIM(CLEAN(TEXT(_xlpm.k,"@"))), TRIM(CLEAN(TEXT(kbli!$C$2:$C$1787,"@"))), kbli!$D$2:$D$1787, "" ), "" ) )), _xlfn.TEXTJOIN(" | ", TRUE, _xlpm.hasil) ) ) )} -> Industri Produk Makanan Lainnya
A3: 27902952 | B3: AHMADUN | C3: Aktif | D3: [Kegiatan Usaha: -, Kategori: -, KBLI: 01262] | E3: UNDEFINED | F3: OSS - Perorangan | G3: {=IFERROR( _xlfn.TEXTJOIN(", ", TRUE, TEXT(TRIM(_xlfn.TEXTAFTER( _xlfn.TEXTBEFORE( _xlfn.FILTERXML("<t><s>" & SUBSTITUTE(D3, ";", "</s><s>") & "</s></t>", "//s"), "]" ), "KBLI:" )), "00000") ), "")} -> 01262 | H3: {=IF(G3="","", _xlfn.TEXTJOIN(", ",TRUE, _xlfn.UNIQUE( _xlfn.MAP( _xlfn.TEXTSPLIT(G3,","),_xlfn.LAMBDA(_xlpm.k, _xlfn.LET( _xlpm.kode,TRIM(TEXT(_xlpm.k,"00000")), _xlpm.d,--LEFT(_xlpm.kode,2), IF(AND(_xlpm.d>=1,_xlpm.d<=3),"A", IF(AND(_xlpm.d>=5,_xlpm.d<=9),"B", IF(AND(_xlpm.d>=10,_xlpm.d<=33),"C", IF(_xlpm.d=35,"D", IF(AND(_xlpm.d>=36,_xlpm.d<=39),"E", IF(AND(_xlpm.d>=41,_xlpm.d<=43),"F", IF(AND(_xlpm.d>=45,_xlpm.d<=47),"G", IF(AND(_xlpm.d>=49,_xlpm.d<=53),"H", IF(AND(_xlpm.d>=55,_xlpm.d<=56),"I", IF(AND(_xlpm.d>=58,_xlpm.d<=63),"J", IF(AND(_xlpm.d>=64,_xlpm.d<=66),"K", IF(_xlpm.d=68,"L", IF(AND(_xlpm.d>=69,_xlpm.d<=75),"M", IF(AND(_xlpm.d>=77,_xlpm.d<=82),"N", IF(_xlpm.d=84,"O", IF(_xlpm.d=85,"P", IF(AND(_xlpm.d>=86,_xlpm.d<=88),"Q", IF(AND(_xlpm.d>=90,_xlpm.d<=93),"R", IF(AND(_xlpm.d>=94,_xlpm.d<=96),"S", IF(AND(_xlpm.d>=97,_xlpm.d<=98),"T", IF(_xlpm.d=99,"U","Tidak diketahui"))))))))))))))))))))) ) ) ) ) ))} -> A | I3: {=_xlfn.LET( _xlpm.isi, G3, IF(_xlpm.isi="","", _xlfn.LET( _xlpm.daftar, _xlfn.TEXTSPLIT(_xlpm.isi, ","), _xlpm.bersih, TRIM(_xlpm.daftar), _xlpm.hasil, _xlfn.MAP(_xlpm.bersih, _xlfn.LAMBDA(_xlpm.k, IFERROR( _xlfn.XLOOKUP( TRIM(CLEAN(TEXT(_xlpm.k,"@"))), TRIM(CLEAN(TEXT(kbli!$C$2:$C$1787,"@"))), kbli!$D$2:$D$1787, "" ), "" ) )), _xlfn.TEXTJOIN(" | ", TRUE, _xlpm.hasil) ) ) )} -> Perkebunan Buah Kelapa Sawit
A4: 30919191 | B4: SUKENDRO | C4: Aktif | D4: [Kegiatan Usaha: -, Kategori: -, KBLI: 03229] | E4: UNDEFINED | F4: OSS - Perorangan | G4: {=IFERROR( _xlfn.TEXTJOIN(", ", TRUE, TEXT(TRIM(_xlfn.TEXTAFTER( _xlfn.TEXTBEFORE( _xlfn.FILTERXML("<t><s>" & SUBSTITUTE(D4, ";", "</s><s>") & "</s></t>", "//s"), "]" ), "KBLI:" )), "00000") ), "")} -> 03229 | H4: {=IF(G4="","", _xlfn.TEXTJOIN(", ",TRUE, _xlfn.UNIQUE( _xlfn.MAP( _xlfn.TEXTSPLIT(G4,","),_xlfn.LAMBDA(_xlpm.k, _xlfn.LET( _xlpm.kode,TRIM(TEXT(_xlpm.k,"00000")), _xlpm.d,--LEFT(_xlpm.kode,2), IF(AND(_xlpm.d>=1,_xlpm.d<=3),"A", IF(AND(_xlpm.d>=5,_xlpm.d<=9),"B", IF(AND(_xlpm.d>=10,_xlpm.d<=33),"C", IF(_xlpm.d=35,"D", IF(AND(_xlpm.d>=36,_xlpm.d<=39),"E", IF(AND(_xlpm.d>=41,_xlpm.d<=43),"F", IF(AND(_xlpm.d>=45,_xlpm.d<=47),"G", IF(AND(_xlpm.d>=49,_xlpm.d<=53),"H", IF(AND(_xlpm.d>=55,_xlpm.d<=56),"I", IF(AND(_xlpm.d>=58,_xlpm.d<=63),"J", IF(AND(_xlpm.d>=64,_xlpm.d<=66),"K", IF(_xlpm.d=68,"L", IF(AND(_xlpm.d>=69,_xlpm.d<=75),"M", IF(AND(_xlpm.d>=77,_xlpm.d<=82),"N", IF(_xlpm.d=84,"O", IF(_xlpm.d=85,"P", IF(AND(_xlpm.d>=86,_xlpm.d<=88),"Q", IF(AND(_xlpm.d>=90,_xlpm.d<=93),"R", IF(AND(_xlpm.d>=94,_xlpm.d<=96),"S", IF(AND(_xlpm.d>=97,_xlpm.d<=98),"T", IF(_xlpm.d=99,"U","Tidak diketahui"))))))))))))))))))))) ) ) ) ) ))} -> A | I4: {=_xlfn.LET( _xlpm.isi, G4, IF(_xlpm.isi="","", _xlfn.LET( _xlpm.daftar, _xlfn.TEXTSPLIT(_xlpm.isi, ","), _xlpm.bersih, TRIM(_xlpm.daftar), _xlpm.hasil, _xlfn.MAP(_xlpm.bersih, _xlfn.LAMBDA(_xlpm.k, IFERROR( _xlfn.XLOOKUP( TRIM(CLEAN(TEXT(_xlpm.k,"@"))), TRIM(CLEAN(TEXT(kbli!$C$2:$C$1787,"@"))), kbli!$D$2:$D$1787, "" ), "" ) )), _xlfn.TEXTJOIN(" | ", TRUE, _xlpm.hasil) ) ) )} -> Budidaya Ikan Air Tawar di Media Lainnya
A5: 27912223 | B5: KOSIDAH | C5: Aktif | D5: [Kegiatan Usaha: -, Kategori: -, KBLI: 01262]; [Kegiatan Usaha: -, Kategori: -, KBLI: 01262] | E5: UNDEFINED | F5: OSS - Perorangan | G5: {=IFERROR( _xlfn.TEXTJOIN(", ", TRUE, TEXT(TRIM(_xlfn.TEXTAFTER( _xlfn.TEXTBEFORE( _xlfn.FILTERXML("<t><s>" & SUBSTITUTE(D5, ";", "</s><s>") & "</s></t>", "//s"), "]" ), "KBLI:" )), "00000") ), "")} -> 01262, 01262 | H5: {=IF(G5="","", _xlfn.TEXTJOIN(", ",TRUE, _xlfn.UNIQUE( _xlfn.MAP( _xlfn.TEXTSPLIT(G5,","),_xlfn.LAMBDA(_xlpm.k, _xlfn.LET( _xlpm.kode,TRIM(TEXT(_xlpm.k,"00000")), _xlpm.d,--LEFT(_xlpm.kode,2), IF(AND(_xlpm.d>=1,_xlpm.d<=3),"A", IF(AND(_xlpm.d>=5,_xlpm.d<=9),"B", IF(AND(_xlpm.d>=10,_xlpm.d<=33),"C", IF(_xlpm.d=35,"D", IF(AND(_xlpm.d>=36,_xlpm.d<=39),"E", IF(AND(_xlpm.d>=41,_xlpm.d<=43),"F", IF(AND(_xlpm.d>=45,_xlpm.d<=47),"G", IF(AND(_xlpm.d>=49,_xlpm.d<=53),"H", IF(AND(_xlpm.d>=55,_xlpm.d<=56),"I", IF(AND(_xlpm.d>=58,_xlpm.d<=63),"J", IF(AND(_xlpm.d>=64,_xlpm.d<=66),"K", IF(_xlpm.d=68,"L", IF(AND(_xlpm.d>=69,_xlpm.d<=75),"M", IF(AND(_xlpm.d>=77,_xlpm.d<=82),"N", IF(_xlpm.d=84,"O", IF(_xlpm.d=85,"P", IF(AND(_xlpm.d>=86,_xlpm.d<=88),"Q", IF(AND(_xlpm.d>=90,_xlpm.d<=93),"R", IF(AND(_xlpm.d>=94,_xlpm.d<=96),"S", IF(AND(_xlpm.d>=97,_xlpm.d<=98),"T", IF(_xlpm.d=99,"U","Tidak diketahui"))))))))))))))))))))) ) ) ) ) ))} -> A, A | I5: {=_xlfn.LET( _xlpm.isi, G5, IF(_xlpm.isi="","", _xlfn.LET( _xlpm.daftar, _xlfn.TEXTSPLIT(_xlpm.isi, ","), _xlpm.bersih, TRIM(_xlpm.daftar), _xlpm.hasil, _xlfn.MAP(_xlpm.bersih, _xlfn.LAMBDA(_xlpm.k, IFERROR( _xlfn.XLOOKUP( TRIM(CLEAN(TEXT(_xlpm.k,"@"))), TRIM(CLEAN(TEXT(kbli!$C$2:$C$1787,"@"))), kbli!$D$2:$D$1787, "" ), "" ) )), _xlfn.TEXTJOIN(" | ", TRUE, _xlpm.hasil) ) ) )} -> Perkebunan Buah Kelapa Sawit | Perkebunan Buah Kelapa Sawit
A6: 28298459 | B6: ANDI DEDY SETIAWAN | C6: Aktif | D6: [Kegiatan Usaha: -, Kategori: -, KBLI: 45407] | E6: UNDEFINED | F6: OSS - Perorangan | G6: {=IFERROR( _xlfn.TEXTJOIN(", ", TRUE, TEXT(TRIM(_xlfn.TEXTAFTER( _xlfn.TEXTBEFORE( _xlfn.FILTERXML("<t><s>" & SUBSTITUTE(D6, ";", "</s><s>") & "</s></t>", "//s"), "]" ), "KBLI:" )), "00000") ), "")} -> 45407 | H6: {=IF(G6="","", _xlfn.TEXTJOIN(", ",TRUE, _xlfn.UNIQUE( _xlfn.MAP( _xlfn.TEXTSPLIT(G6,","),_xlfn.LAMBDA(_xlpm.k, _xlfn.LET( _xlpm.kode,TRIM(TEXT(_xlpm.k,"00000")), _xlpm.d,--LEFT(_xlpm.kode,2), IF(AND(_xlpm.d>=1,_xlpm.d<=3),"A", IF(AND(_xlpm.d>=5,_xlpm.d<=9),"B", IF(AND(_xlpm.d>=10,_xlpm.d<=33),"C", IF(_xlpm.d=35,"D", IF(AND(_xlpm.d>=36,_xlpm.d<=39),"E", IF(AND(_xlpm.d>=41,_xlpm.d<=43),"F", IF(AND(_xlpm.d>=45,_xlpm.d<=47),"G", IF(AND(_xlpm.d>=49,_xlpm.d<=53),"H", IF(AND(_xlpm.d>=55,_xlpm.d<=56),"I", IF(AND(_xlpm.d>=58,_xlpm.d<=63),"J", IF(AND(_xlpm.d>=64,_xlpm.d<=66),"K", IF(_xlpm.d=68,"L", IF(AND(_xlpm.d>=69,_xlpm.d<=75),"M", IF(AND(_xlpm.d>=77,_xlpm.d<=82),"N", IF(_xlpm.d=84,"O", IF(_xlpm.d=85,"P", IF(AND(_xlpm.d>=86,_xlpm.d<=88),"Q", IF(AND(_xlpm.d>=90,_xlpm.d<=93),"R", IF(AND(_xlpm.d>=94,_xlpm.d<=96),"S", IF(AND(_xlpm.d>=97,_xlpm.d<=98),"T", IF(_xlpm.d=99,"U","Tidak diketahui"))))))))))))))))))))) ) ) ) ) ))} -> G | I6: {=_xlfn.LET( _xlpm.isi, G6, IF(_xlpm.isi="","", _xlfn.LET( _xlpm.daftar, _xlfn.TEXTSPLIT(_xlpm.isi, ","), _xlpm.bersih, TRIM(_xlpm.daftar), _xlpm.hasil, _xlfn.MAP(_xlpm.bersih, _xlfn.LAMBDA(_xlpm.k, IFERROR( _xlfn.XLOOKUP( TRIM(CLEAN(TEXT(_xlpm.k,"@"))), TRIM(CLEAN(TEXT(kbli!$C$2:$C$1787,"@"))), kbli!$D$2:$D$1787, "" ), "" ) )), _xlfn.TEXTJOIN(" | ", TRUE, _xlpm.hasil) ) ) )} -> Reparasi Dan Perawatan Sepeda Motor
A7: 28275162 | B7: DARMIYATI | C7: Aktif | D7: [Kegiatan Usaha: -, Kategori: -, KBLI: 47242] | E7: UNDEFINED | F7: OSS - Perorangan | G7: {=IFERROR( _xlfn.TEXTJOIN(", ", TRUE, TEXT(TRIM(_xlfn.TEXTAFTER( _xlfn.TEXTBEFORE( _xlfn.FILTERXML("<t><s>" & SUBSTITUTE(D7, ";", "</s><s>") & "</s></t>", "//s"), "]" ), "KBLI:" )), "00000") ), "")} -> 47242 | H7: {=IF(G7="","", _xlfn.TEXTJOIN(", ",TRUE, _xlfn.UNIQUE( _xlfn.MAP( _xlfn.TEXTSPLIT(G7,","),_xlfn.LAMBDA(_xlpm.k, _xlfn.LET( _xlpm.kode,TRIM(TEXT(_xlpm.k,"00000")), _xlpm.d,--LEFT(_xlpm.kode,2), IF(AND(_xlpm.d>=1,_xlpm.d<=3),"A", IF(AND(_xlpm.d>=5,_xlpm.d<=9),"B", IF(AND(_xlpm.d>=10,_xlpm.d<=33),"C", IF(_xlpm.d=35,"D", IF(AND(_xlpm.d>=36,_xlpm.d<=39),"E", IF(AND(_xlpm.d>=41,_xlpm.d<=43),"F", IF(AND(_xlpm.d>=45,_xlpm.d<=47),"G", IF(AND(_xlpm.d>=49,_xlpm.d<=53),"H", IF(AND(_xlpm.d>=55,_xlpm.d<=56),"I", IF(AND(_xlpm.d>=58,_xlpm.d<=63),"J", IF(AND(_xlpm.d>=64,_xlpm.d<=66),"K", IF(_xlpm.d=68,"L", IF(AND(_xlpm.d>=69,_xlpm.d<=75),"M", IF(AND(_xlpm.d>=77,_xlpm.d<=82),"N", IF(_xlpm.d=84,"O", IF(_xlpm.d=85,"P", IF(AND(_xlpm.d>=86,_xlpm.d<=88),"Q", IF(AND(_xlpm.d>=90,_xlpm.d<=93),"R", IF(AND(_xlpm.d>=94,_xlpm.d<=96),"S", IF(AND(_xlpm.d>=97,_xlpm.d<=98),"T", IF(_xlpm.d=99,"U","Tidak diketahui"))))))))))))))))))))) ) ) ) ) ))} -> G | I7: {=_xlfn.LET( _xlpm.isi, G7, IF(_xlpm.isi="","", _xlfn.LET( _xlpm.daftar, _xlfn.TEXTSPLIT(_xlpm.isi, ","), _xlpm.bersih, TRIM(_xlpm.daftar), _xlpm.hasil, _xlfn.MAP(_xlpm.bersih, _xlfn.LAMBDA(_xlpm.k, IFERROR( _xlfn.XLOOKUP( TRIM(CLEAN(TEXT(_xlpm.k,"@"))), TRIM(CLEAN(TEXT(kbli!$C$2:$C$1787,"@"))), kbli!$D$2:$D$1787, "" ), "" ) )), _xlfn.TEXTJOIN(" | ", TRUE, _xlpm.hasil) ) ) )} -> Perdagangan Eceran Roti, Kue Kering, serta Kue Basah dan Sejenisnya
A8: 29557240 | B8: ROZULA | C8: Aktif | D8: [Kegiatan Usaha: -, Kategori: -, KBLI: 47112] | E8: UNDEFINED | F8: OSS - Perorangan | G8: {=IFERROR( _xlfn.TEXTJOIN(", ", TRUE, TEXT(TRIM(_xlfn.TEXTAFTER( _xlfn.TEXTBEFORE( _xlfn.FILTERXML("<t><s>" & SUBSTITUTE(D8, ";", "</s><s>") & "</s></t>", "//s"), "]" ), "KBLI:" )), "00000") ), "")} -> 47112 | H8: {=IF(G8="","", _xlfn.TEXTJOIN(", ",TRUE, _xlfn.UNIQUE( _xlfn.MAP( _xlfn.TEXTSPLIT(G8,","),_xlfn.LAMBDA(_xlpm.k, _xlfn.LET( _xlpm.kode,TRIM(TEXT(_xlpm.k,"00000")), _xlpm.d,--LEFT(_xlpm.kode,2), IF(AND(_xlpm.d>=1,_xlpm.d<=3),"A", IF(AND(_xlpm.d>=5,_xlpm.d<=9),"B", IF(AND(_xlpm.d>=10,_xlpm.d<=33),"C", IF(_xlpm.d=35,"D", IF(AND(_xlpm.d>=36,_xlpm.d<=39),"E", IF(AND(_xlpm.d>=41,_xlpm.d<=43),"F", IF(AND(_xlpm.d>=45,_xlpm.d<=47),"G", IF(AND(_xlpm.d>=49,_xlpm.d<=53),"H", IF(AND(_xlpm.d>=55,_xlpm.d<=56),"I", IF(AND(_xlpm.d>=58,_xlpm.d<=63),"J", IF(AND(_xlpm.d>=64,_xlpm.d<=66),"K", IF(_xlpm.d=68,"L", IF(AND(_xlpm.d>=69,_xlpm.d<=75),"M", IF(AND(_xlpm.d>=77,_xlpm.d<=82),"N", IF(_xlpm.d=84,"O", IF(_xlpm.d=85,"P", IF(AND(_xlpm.d>=86,_xlpm.d<=88),"Q", IF(AND(_xlpm.d>=90,_xlpm.d<=93),"R", IF(AND(_xlpm.d>=94,_xlpm.d<=96),"S", IF(AND(_xlpm.d>=97,_xlpm.d<=98),"T", IF(_xlpm.d=99,"U","Tidak diketahui"))))))))))))))))))))) ) ) ) ) ))} -> G | I8: {=_xlfn.LET( _xlpm.isi, G8, IF(_xlpm.isi="","", _xlfn.LET( _xlpm.daftar, _xlfn.TEXTSPLIT(_xlpm.isi, ","), _xlpm.bersih, TRIM(_xlpm.daftar), _xlpm.hasil, _xlfn.MAP(_xlpm.bersih, _xlfn.LAMBDA(_xlpm.k, IFERROR( _xlfn.XLOOKUP( TRIM(CLEAN(TEXT(_xlpm.k,"@"))), TRIM(CLEAN(TEXT(kbli!$C$2:$C$1787,"@"))), kbli!$D$2:$D$1787, "" ), "" ) )), _xlfn.TEXTJOIN(" | ", TRUE, _xlpm.hasil) ) ) )} -> Perdagangan Eceran Berbagai Macam Barang Yang Utamanya Makanan, Minuman Atau Tembakau Bukan Di Minimarket/Supermarket/Hypermarket (Tradisional)
A9: 28745464 | B9: HIPZO | C9: Aktif | D9: [Kegiatan Usaha: -, Kategori: -, KBLI: 01262] | E9: UNDEFINED | F9: OSS - Perorangan | G9: {=IFERROR( _xlfn.TEXTJOIN(", ", TRUE, TEXT(TRIM(_xlfn.TEXTAFTER( _xlfn.TEXTBEFORE( _xlfn.FILTERXML("<t><s>" & SUBSTITUTE(D9, ";", "</s><s>") & "</s></t>", "//s"), "]" ), "KBLI:" )), "00000") ), "")} -> 01262 | H9: {=IF(G9="","", _xlfn.TEXTJOIN(", ",TRUE, _xlfn.UNIQUE( _xlfn.MAP( _xlfn.TEXTSPLIT(G9,","),_xlfn.LAMBDA(_xlpm.k, _xlfn.LET( _xlpm.kode,TRIM(TEXT(_xlpm.k,"00000")), _xlpm.d,--LEFT(_xlpm.kode,2), IF(AND(_xlpm.d>=1,_xlpm.d<=3),"A", IF(AND(_xlpm.d>=5,_xlpm.d<=9),"B", IF(AND(_xlpm.d>=10,_xlpm.d<=33),"C", IF(_xlpm.d=35,"D", IF(AND(_xlpm.d>=36,_xlpm.d<=39),"E", IF(AND(_xlpm.d>=41,_xlpm.d<=43),"F", IF(AND(_xlpm.d>=45,_xlpm.d<=47),"G", IF(AND(_xlpm.d>=49,_xlpm.d<=53),"H", IF(AND(_xlpm.d>=55,_xlpm.d<=56),"I", IF(AND(_xlpm.d>=58,_xlpm.d<=63),"J", IF(AND(_xlpm.d>=64,_xlpm.d<=66),"K", IF(_xlpm.d=68,"L", IF(AND(_xlpm.d>=69,_xlpm.d<=75),"M", IF(AND(_xlpm.d>=77,_xlpm.d<=82),"N", IF(_xlpm.d=84,"O", IF(_xlpm.d=85,"P", IF(AND(_xlpm.d>=86,_xlpm.d<=88),"Q", IF(AND(_xlpm.d>=90,_xlpm.d<=93),"R", IF(AND(_xlpm.d>=94,_xlpm.d<=96),"S", IF(AND(_xlpm.d>=97,_xlpm.d<=98),"T", IF(_xlpm.d=99,"U","Tidak diketahui"))))))))))))))))))))) ) ) ) ) ))} -> A | I9: {=_xlfn.LET( _xlpm.isi, G9, IF(_xlpm.isi="","", _xlfn.LET( _xlpm.daftar, _xlfn.TEXTSPLIT(_xlpm.isi, ","), _xlpm.bersih, TRIM(_xlpm.daftar), _xlpm.hasil, _xlfn.MAP(_xlpm.bersih, _xlfn.LAMBDA(_xlpm.k, IFERROR( _xlfn.XLOOKUP( TRIM(CLEAN(TEXT(_xlpm.k,"@"))), TRIM(CLEAN(TEXT(kbli!$C$2:$C$1787,"@"))), kbli!$D$2:$D$1787, "" ), "" ) )), _xlfn.TEXTJOIN(" | ", TRUE, _xlpm.hasil) ) ) )} -> Perkebunan Buah Kelapa Sawit
A10: 30940346 | B10: MUHAMAD SOLIHIN | C10: Aktif | D10: [Kegiatan Usaha: -, Kategori: -, KBLI: 01262] | E10: UNDEFINED | F10: OSS - Perorangan | G10: {=IFERROR( _xlfn.TEXTJOIN(", ", TRUE, TEXT(TRIM(_xlfn.TEXTAFTER( _xlfn.TEXTBEFORE( _xlfn.FILTERXML("<t><s>" & SUBSTITUTE(D10, ";", "</s><s>") & "</s></t>", "//s"), "]" ), "KBLI:" )), "00000") ), "")} -> 01262 | H10: {=IF(G10="","", _xlfn.TEXTJOIN(", ",TRUE, _xlfn.UNIQUE( _xlfn.MAP( _xlfn.TEXTSPLIT(G10,","),_xlfn.LAMBDA(_xlpm.k, _xlfn.LET( _xlpm.kode,TRIM(TEXT(_xlpm.k,"00000")), _xlpm.d,--LEFT(_xlpm.kode,2), IF(AND(_xlpm.d>=1,_xlpm.d<=3),"A", IF(AND(_xlpm.d>=5,_xlpm.d<=9),"B", IF(AND(_xlpm.d>=10,_xlpm.d<=33),"C", IF(_xlpm.d=35,"D", IF(AND(_xlpm.d>=36,_xlpm.d<=39),"E", IF(AND(_xlpm.d>=41,_xlpm.d<=43),"F", IF(AND(_xlpm.d>=45,_xlpm.d<=47),"G", IF(AND(_xlpm.d>=49,_xlpm.d<=53),"H", IF(AND(_xlpm.d>=55,_xlpm.d<=56),"I", IF(AND(_xlpm.d>=58,_xlpm.d<=63),"J", IF(AND(_xlpm.d>=64,_xlpm.d<=66),"K", IF(_xlpm.d=68,"L", IF(AND(_xlpm.d>=69,_xlpm.d<=75),"M", IF(AND(_xlpm.d>=77,_xlpm.d<=82),"N", IF(_xlpm.d=84,"O", IF(_xlpm.d=85,"P", IF(AND(_xlpm.d>=86,_xlpm.d<=88),"Q", IF(AND(_xlpm.d>=90,_xlpm.d<=93),"R", IF(AND(_xlpm.d>=94,_xlpm.d<=96),"S", IF(AND(_xlpm.d>=97,_xlpm.d<=98),"T", IF(_xlpm.d=99,"U","Tidak diketahui"))))))))))))))))))))) ) ) ) ) ))} -> A | I10: {=_xlfn.LET( _xlpm.isi, G10, IF(_xlpm.isi="","", _xlfn.LET( _xlpm.daftar, _xlfn.TEXTSPLIT(_xlpm.isi, ","), _xlpm.bersih, TRIM(_xlpm.daftar), _xlpm.hasil, _xlfn.MAP(_xlpm.bersih, _xlfn.LAMBDA(_xlpm.k, IFERROR( _xlfn.XLOOKUP( TRIM(CLEAN(TEXT(_xlpm.k,"@"))), TRIM(CLEAN(TEXT(kbli!$C$2:$C$1787,"@"))), kbli!$D$2:$D$1787, "" ), "" ) )), _xlfn.TEXTJOIN(" | ", TRUE, _xlpm.hasil) ) ) )} -> Perkebunan Buah Kelapa Sawit
A11: 32474232 | B11: HOLIJAH | C11: Aktif | D11: [Kegiatan Usaha: -, Kategori: -, KBLI: 47213] | E11: UNDEFINED | F11: OSS - Perorangan | G11: {=IFERROR( _xlfn.TEXTJOIN(", ", TRUE, TEXT(TRIM(_xlfn.TEXTAFTER( _xlfn.TEXTBEFORE( _xlfn.FILTERXML("<t><s>" & SUBSTITUTE(D11, ";", "</s><s>") & "</s></t>", "//s"), "]" ), "KBLI:" )), "00000") ), "")} -> 47213 | H11: {=IF(G11="","", _xlfn.TEXTJOIN(", ",TRUE, _xlfn.UNIQUE( _xlfn.MAP( _xlfn.TEXTSPLIT(G11,","),_xlfn.LAMBDA(_xlpm.k, _xlfn.LET( _xlpm.kode,TRIM(TEXT(_xlpm.k,"00000")), _xlpm.d,--LEFT(_xlpm.kode,2), IF(AND(_xlpm.d>=1,_xlpm.d<=3),"A", IF(AND(_xlpm.d>=5,_xlpm.d<=9),"B", IF(AND(_xlpm.d>=10,_xlpm.d<=33),"C", IF(_xlpm.d=35,"D", IF(AND(_xlpm.d>=36,_xlpm.d<=39),"E", IF(AND(_xlpm.d>=41,_xlpm.d<=43),"F", IF(AND(_xlpm.d>=45,_xlpm.d<=47),"G", IF(AND(_xlpm.d>=49,_xlpm.d<=53),"H", IF(AND(_xlpm.d>=55,_xlpm.d<=56),"I", IF(AND(_xlpm.d>=58,_xlpm.d<=63),"J", IF(AND(_xlpm.d>=64,_xlpm.d<=66),"K", IF(_xlpm.d=68,"L", IF(AND(_xlpm.d>=69,_xlpm.d<=75),"M", IF(AND(_xlpm.d>=77,_xlpm.d<=82),"N", IF(_xlpm.d=84,"O", IF(_xlpm.d=85,"P", IF(AND(_xlpm.d>=86,_xlpm.d<=88),"Q", IF(AND(_xlpm.d>=90,_xlpm.d<=93),"R", IF(AND(_xlpm.d>=94,_xlpm.d<=96),"S", IF(AND(_xlpm.d>=97,_xlpm.d<=98),"T", IF(_xlpm.d=99,"U","Tidak diketahui"))))))))))))))))))))) ) ) ) ) ))} -> G | I11: {=_xlfn.LET( _xlpm.isi, G11, IF(_xlpm.isi="","", _xlfn.LET( _xlpm.daftar, _xlfn.TEXTSPLIT(_xlpm.isi, ","), _xlpm.bersih, TRIM(_xlpm.daftar), _xlpm.hasil, _xlfn.MAP(_xlpm.bersih, _xlfn.LAMBDA(_xlpm.k, IFERROR( _xlfn.XLOOKUP( TRIM(CLEAN(TEXT(_xlpm.k,"@"))), TRIM(CLEAN(TEXT(kbli!$C$2:$C$1787,"@"))), kbli!$D$2:$D$1787, "" ), "" ) )), _xlfn.TEXTJOIN(" | ", TRUE, _xlpm.hasil) ) ) )} -> Perdagangan Eceran Sayuran
A12: 27135608 | B12: ZAHIDAH | C12: Aktif | D12: [Kegiatan Usaha: -, Kategori: -, KBLI: 10792] | E12: UNDEFINED | F12: OSS - Perorangan | G12: {=IFERROR( _xlfn.TEXTJOIN(", ", TRUE, TEXT(TRIM(_xlfn.TEXTAFTER( _xlfn.TEXTBEFORE( _xlfn.FILTERXML("<t><s>" & SUBSTITUTE(D12, ";", "</s><s>") & "</s></t>", "//s"), "]" ), "KBLI:" )), "00000") ), "")} -> 10792 | H12: {=IF(G12="","", _xlfn.TEXTJOIN(", ",TRUE, _xlfn.UNIQUE( _xlfn.MAP( _xlfn.TEXTSPLIT(G12,","),_xlfn.LAMBDA(_xlpm.k, _xlfn.LET( _xlpm.kode,TRIM(TEXT(_xlpm.k,"00000")), _xlpm.d,--LEFT(_xlpm.kode,2), IF(AND(_xlpm.d>=1,_xlpm.d<=3),"A", IF(AND(_xlpm.d>=5,_xlpm.d<=9),"B", IF(AND(_xlpm.d>=10,_xlpm.d<=33),"C", IF(_xlpm.d=35,"D", IF(AND(_xlpm.d>=36,_xlpm.d<=39),"E", IF(AND(_xlpm.d>=41,_xlpm.d<=43),"F", IF(AND(_xlpm.d>=45,_xlpm.d<=47),"G", IF(AND(_xlpm.d>=49,_xlpm.d<=53),"H", IF(AND(_xlpm.d>=55,_xlpm.d<=56),"I", IF(AND(_xlpm.d>=58,_xlpm.d<=63),"J", IF(AND(_xlpm.d>=64,_xlpm.d<=66),"K", IF(_xlpm.d=68,"L", IF(AND(_xlpm.d>=69,_xlpm.d<=75),"M", IF(AND(_xlpm.d>=77,_xlpm.d<=82),"N", IF(_xlpm.d=84,"O", IF(_xlpm.d=85,"P", IF(AND(_xlpm.d>=86,_xlpm.d<=88),"Q", IF(AND(_xlpm.d>=90,_xlpm.d<=93),"R", IF(AND(_xlpm.d>=94,_xlpm.d<=96),"S", IF(AND(_xlpm.d>=97,_xlpm.d<=98),"T", IF(_xlpm.d=99,"U","Tidak diketahui"))))))))))))))))))))) ) ) ) ) ))} -> C | I12: {=_xlfn.LET( _xlpm.isi, G12, IF(_xlpm.isi="","", _xlfn.LET( _xlpm.daftar, _xlfn.TEXTSPLIT(_xlpm.isi, ","), _xlpm.bersih, TRIM(_xlpm.daftar), _xlpm.hasil, _xlfn.MAP(_xlpm.bersih, _xlfn.LAMBDA(_xlpm.k, IFERROR( _xlfn.XLOOKUP( TRIM(CLEAN(TEXT(_xlpm.k,"@"))), TRIM(CLEAN(TEXT(kbli!$C$2:$C$1787,"@"))), kbli!$D$2:$D$1787, "" ), "" ) )), _xlfn.TEXTJOIN(" | ", TRUE, _xlpm.hasil) ) ) )} -> Industri Kue Basah
A13: 29371287 | B13: Hasanah | C13: Aktif | D13: [Kegiatan Usaha: -, Kategori: -, KBLI: 47245] | E13: UNDEFINED | F13: OSS - Perorangan | G13: {=IFERROR( _xlfn.TEXTJOIN(", ", TRUE, TEXT(TRIM(_xlfn.TEXTAFTER( _xlfn.TEXTBEFORE( _xlfn.FILTERXML("<t><s>" & SUBSTITUTE(D13, ";", "</s><s>") & "</s></t>", "//s"), "]" ), "KBLI:" )), "00000") ), "")} -> 47245 | H13: {=IF(G13="","", _xlfn.TEXTJOIN(", ",TRUE, _xlfn.UNIQUE( _xlfn.MAP( _xlfn.TEXTSPLIT(G13,","),_xlfn.LAMBDA(_xlpm.k, _xlfn.LET( _xlpm.kode,TRIM(TEXT(_xlpm.k,"00000")), _xlpm.d,--LEFT(_xlpm.kode,2), IF(AND(_xlpm.d>=1,_xlpm.d<=3),"A", IF(AND(_xlpm.d>=5,_xlpm.d<=9),"B", IF(AND(_xlpm.d>=10,_xlpm.d<=33),"C", IF(_xlpm.d=35,"D", IF(AND(_xlpm.d>=36,_xlpm.d<=39),"E", IF(AND(_xlpm.d>=41,_xlpm.d<=43),"F", IF(AND(_xlpm.d>=45,_xlpm.d<=47),"G", IF(AND(_xlpm.d>=49,_xlpm.d<=53),"H", IF(AND(_xlpm.d>=55,_xlpm.d<=56),"I", IF(AND(_xlpm.d>=58,_xlpm.d<=63),"J", IF(AND(_xlpm.d>=64,_xlpm.d<=66),"K", IF(_xlpm.d=68,"L", IF(AND(_xlpm.d>=69,_xlpm.d<=75),"M", IF(AND(_xlpm.d>=77,_xlpm.d<=82),"N", IF(_xlpm.d=84,"O", IF(_xlpm.d=85,"P", IF(AND(_xlpm.d>=86,_xlpm.d<=88),"Q", IF(AND(_xlpm.d>=90,_xlpm.d<=93),"R", IF(AND(_xlpm.d>=94,_xlpm.d<=96),"S", IF(AND(_xlpm.d>=97,_xlpm.d<=98),"T", IF(_xlpm.d=99,"U","Tidak diketahui"))))))))))))))))))))) ) ) ) ) ))} -> G | I13: {=_xlfn.LET( _xlpm.isi, G13, IF(_xlpm.isi="","", _xlfn.LET( _xlpm.daftar, _xlfn.TEXTSPLIT(_xlpm.isi, ","), _xlpm.bersih, TRIM(_xlpm.daftar), _xlpm.hasil, _xlfn.MAP(_xlpm.bersih, _xlfn.LAMBDA(_xlpm.k, IFERROR( _xlfn.XLOOKUP( TRIM(CLEAN(TEXT(_xlpm.k,"@"))), TRIM(CLEAN(TEXT(kbli!$C$2:$C$1787,"@"))), kbli!$D$2:$D$1787, "" ), "" ) )), _xlfn.TEXTJOIN(" | ", TRUE, _xlpm.hasil) ) ) )} -> Perdagangan Eceran Daging dan Ikan Olahan
... A3159: 31237751 | B3159: TRISDIANA | C3159: Aktif | D3159: [Kegiatan Usaha: -, Kategori: -, KBLI: 47753] | E3159: UNDEFINED | F3159: OSS - Perorangan | G3159: {=IFERROR( _xlfn.TEXTJOIN(", ", TRUE, TEXT(TRIM(_xlfn.TEXTAFTER( _xlfn.TEXTBEFORE( _xlfn.FILTERXML("<t><s>" & SUBSTITUTE(D3159, ";", "</s><s>") & "</s></t>", "//s"), "]" ), "KBLI:" )), "00000") ), "")} -> 47753 | H3159: {=IF(G3159="","", _xlfn.TEXTJOIN(", ",TRUE, _xlfn.UNIQUE( _xlfn.MAP( _xlfn.TEXTSPLIT(G3159,","),_xlfn.LAMBDA(_xlpm.k, _xlfn.LET( _xlpm.kode,TRIM(TEXT(_xlpm.k,"00000")), _xlpm.d,--LEFT(_xlpm.kode,2), IF(AND(_xlpm.d>=1,_xlpm.d<=3),"A", IF(AND(_xlpm.d>=5,_xlpm.d<=9),"B", IF(AND(_xlpm.d>=10,_xlpm.d<=33),"C", IF(_xlpm.d=35,"D", IF(AND(_xlpm.d>=36,_xlpm.d<=39),"E", IF(AND(_xlpm.d>=41,_xlpm.d<=43),"F", IF(AND(_xlpm.d>=45,_xlpm.d<=47),"G", IF(AND(_xlpm.d>=49,_xlpm.d<=53),"H", IF(AND(_xlpm.d>=55,_xlpm.d<=56),"I", IF(AND(_xlpm.d>=58,_xlpm.d<=63),"J", IF(AND(_xlpm.d>=64,_xlpm.d<=66),"K", IF(_xlpm.d=68,"L", IF(AND(_xlpm.d>=69,_xlpm.d<=75),"M", IF(AND(_xlpm.d>=77,_xlpm.d<=82),"N", IF(_xlpm.d=84,"O", IF(_xlpm.d=85,"P", IF(AND(_xlpm.d>=86,_xlpm.d<=88),"Q", IF(AND(_xlpm.d>=90,_xlpm.d<=93),"R", IF(AND(_xlpm.d>=94,_xlpm.d<=96),"S", IF(AND(_xlpm.d>=97,_xlpm.d<=98),"T", IF(_xlpm.d=99,"U","Tidak diketahui"))))))))))))))))))))) ) ) ) ) ))} -> G | I3159: {=_xlfn.LET( _xlpm.isi, G3159, IF(_xlpm.isi="","", _xlfn.LET( _xlpm.daftar, _xlfn.TEXTSPLIT(_xlpm.isi, ","), _xlpm.bersih, TRIM(_xlpm.daftar), _xlpm.hasil, _xlfn.MAP(_xlpm.bersih, _xlfn.LAMBDA(_xlpm.k, IFERROR( _xlfn.XLOOKUP( TRIM(CLEAN(TEXT(_xlpm.k,"@"))), TRIM(CLEAN(TEXT(kbli!$C$2:$C$1787,"@"))), kbli!$D$2:$D$1787, "" ), "" ) )), _xlfn.TEXTJOIN(" | ", TRUE, _xlpm.hasil) ) ) )} -> Perdagangan Eceran Ikan Hias
G3160: {=IFERROR( _xlfn.TEXTJOIN(", ", TRUE, TEXT(TRIM(_xlfn.TEXTAFTER( _xlfn.TEXTBEFORE( _xlfn.FILTERXML("<t><s>" & SUBSTITUTE(D3160, ";", "</s><s>") & "</s></t>", "//s"), "]" ), "KBLI:" )), "00000") ), "")} | H3160: {=IF(G3160="","", _xlfn.TEXTJOIN(", ",TRUE, _xlfn.UNIQUE( _xlfn.MAP( _xlfn.TEXTSPLIT(G3160,","),_xlfn.LAMBDA(_xlpm.k, _xlfn.LET( _xlpm.kode,TRIM(TEXT(_xlpm.k,"00000")), _xlpm.d,--LEFT(_xlpm.kode,2), IF(AND(_xlpm.d>=1,_xlpm.d<=3),"A", IF(AND(_xlpm.d>=5,_xlpm.d<=9),"B", IF(AND(_xlpm.d>=10,_xlpm.d<=33),"C", IF(_xlpm.d=35,"D", IF(AND(_xlpm.d>=36,_xlpm.d<=39),"E", IF(AND(_xlpm.d>=41,_xlpm.d<=43),"F", IF(AND(_xlpm.d>=45,_xlpm.d<=47),"G", IF(AND(_xlpm.d>=49,_xlpm.d<=53),"H", IF(AND(_xlpm.d>=55,_xlpm.d<=56),"I", IF(AND(_xlpm.d>=58,_xlpm.d<=63),"J", IF(AND(_xlpm.d>=64,_xlpm.d<=66),"K", IF(_xlpm.d=68,"L", IF(AND(_xlpm.d>=69,_xlpm.d<=75),"M", IF(AND(_xlpm.d>=77,_xlpm.d<=82),"N", IF(_xlpm.d=84,"O", IF(_xlpm.d=85,"P", IF(AND(_xlpm.d>=86,_xlpm.d<=88),"Q", IF(AND(_xlpm.d>=90,_xlpm.d<=93),"R", IF(AND(_xlpm.d>=94,_xlpm.d<=96),"S", IF(AND(_xlpm.d>=97,_xlpm.d<=98),"T", IF(_xlpm.d=99,"U","Tidak diketahui"))))))))))))))))))))) ) ) ) ) ))} | I3160: {=_xlfn.LET( _xlpm.isi, G3160, IF(_xlpm.isi="","", _xlfn.LET( _xlpm.daftar, _xlfn.TEXTSPLIT(_xlpm.isi, ","), _xlpm.bersih, TRIM(_xlpm.daftar), _xlpm.hasil, _xlfn.MAP(_xlpm.bersih, _xlfn.LAMBDA(_xlpm.k, IFERROR( _xlfn.XLOOKUP( TRIM(CLEAN(TEXT(_xlpm.k,"@"))), TRIM(CLEAN(TEXT(kbli!$C$2:$C$1787,"@"))), kbli!$D$2:$D$1787, "" ), "" ) )), _xlfn.TEXTJOIN(" | ", TRUE, _xlpm.hasil) ) ) )}
G3161: {=IFERROR( _xlfn.TEXTJOIN(", ", TRUE, TEXT(TRIM(_xlfn.TEXTAFTER( _xlfn.TEXTBEFORE( _xlfn.FILTERXML("<t><s>" & SUBSTITUTE(D3161, ";", "</s><s>") & "</s></t>", "//s"), "]" ), "KBLI:" )), "00000") ), "")} | H3161: {=IF(G3161="","", _xlfn.TEXTJOIN(", ",TRUE, _xlfn.UNIQUE( _xlfn.MAP( _xlfn.TEXTSPLIT(G3161,","),_xlfn.LAMBDA(_xlpm.k, _xlfn.LET( _xlpm.kode,TRIM(TEXT(_xlpm.k,"00000")), _xlpm.d,--LEFT(_xlpm.kode,2), IF(AND(_xlpm.d>=1,_xlpm.d<=3),"A", IF(AND(_xlpm.d>=5,_xlpm.d<=9),"B", IF(AND(_xlpm.d>=10,_xlpm.d<=33),"C", IF(_xlpm.d=35,"D", IF(AND(_xlpm.d>=36,_xlpm.d<=39),"E", IF(AND(_xlpm.d>=41,_xlpm.d<=43),"F", IF(AND(_xlpm.d>=45,_xlpm.d<=47),"G", IF(AND(_xlpm.d>=49,_xlpm.d<=53),"H", IF(AND(_xlpm.d>=55,_xlpm.d<=56),"I", IF(AND(_xlpm.d>=58,_xlpm.d<=63),"J", IF(AND(_xlpm.d>=64,_xlpm.d<=66),"K", IF(_xlpm.d=68,"L", IF(AND(_xlpm.d>=69,_xlpm.d<=75),"M", IF(AND(_xlpm.d>=77,_xlpm.d<=82),"N", IF(_xlpm.d=84,"O", IF(_xlpm.d=85,"P", IF(AND(_xlpm.d>=86,_xlpm.d<=88),"Q", IF(AND(_xlpm.d>=90,_xlpm.d<=93),"R", IF(AND(_xlpm.d>=94,_xlpm.d<=96),"S", IF(AND(_xlpm.d>=97,_xlpm.d<=98),"T", IF(_xlpm.d=99,"U","Tidak diketahui"))))))))))))))))))))) ) ) ) ) ))} | I3161: {=_xlfn.LET( _xlpm.isi, G3161, IF(_xlpm.isi="","", _xlfn.LET( _xlpm.daftar, _xlfn.TEXTSPLIT(_xlpm.isi, ","), _xlpm.bersih, TRIM(_xlpm.daftar), _xlpm.hasil, _xlfn.MAP(_xlpm.bersih, _xlfn.LAMBDA(_xlpm.k, IFERROR( _xlfn.XLOOKUP( TRIM(CLEAN(TEXT(_xlpm.k,"@"))), TRIM(CLEAN(TEXT(kbli!$C$2:$C$1787,"@"))), kbli!$D$2:$D$1787, "" ), "" ) )), _xlfn.TEXTJOIN(" | ", TRUE, _xlpm.hasil) ) ) )}
G3162: {=IFERROR( _xlfn.TEXTJOIN(", ", TRUE, TEXT(TRIM(_xlfn.TEXTAFTER( _xlfn.TEXTBEFORE( _xlfn.FILTERXML("<t><s>" & SUBSTITUTE(D3162, ";", "</s><s>") & "</s></t>", "//s"), "]" ), "KBLI:" )), "00000") ), "")} | H3162: {=IF(G3162="","", _xlfn.TEXTJOIN(", ",TRUE, _xlfn.UNIQUE( _xlfn.MAP( _xlfn.TEXTSPLIT(G3162,","),_xlfn.LAMBDA(_xlpm.k, _xlfn.LET( _xlpm.kode,TRIM(TEXT(_xlpm.k,"00000")), _xlpm.d,--LEFT(_xlpm.kode,2), IF(AND(_xlpm.d>=1,_xlpm.d<=3),"A", IF(AND(_xlpm.d>=5,_xlpm.d<=9),"B", IF(AND(_xlpm.d>=10,_xlpm.d<=33),"C", IF(_xlpm.d=35,"D", IF(AND(_xlpm.d>=36,_xlpm.d<=39),"E", IF(AND(_xlpm.d>=41,_xlpm.d<=43),"F", IF(AND(_xlpm.d>=45,_xlpm.d<=47),"G", IF(AND(_xlpm.d>=49,_xlpm.d<=53),"H", IF(AND(_xlpm.d>=55,_xlpm.d<=56),"I", IF(AND(_xlpm.d>=58,_xlpm.d<=63),"J", IF(AND(_xlpm.d>=64,_xlpm.d<=66),"K", IF(_xlpm.d=68,"L", IF(AND(_xlpm.d>=69,_xlpm.d<=75),"M", IF(AND(_xlpm.d>=77,_xlpm.d<=82),"N", IF(_xlpm.d=84,"O", IF(_xlpm.d=85,"P", IF(AND(_xlpm.d>=86,_xlpm.d<=88),"Q", IF(AND(_xlpm.d>=90,_xlpm.d<=93),"R", IF(AND(_xlpm.d>=94,_xlpm.d<=96),"S", IF(AND(_xlpm.d>=97,_xlpm.d<=98),"T", IF(_xlpm.d=99,"U","Tidak diketahui"))))))))))))))))))))) ) ) ) ) ))} | I3162: {=_xlfn.LET( _xlpm.isi, G3162, IF(_xlpm.isi="","", _xlfn.LET( _xlpm.daftar, _xlfn.TEXTSPLIT(_xlpm.isi, ","), _xlpm.bersih, TRIM(_xlpm.daftar), _xlpm.hasil, _xlfn.MAP(_xlpm.bersih, _xlfn.LAMBDA(_xlpm.k, IFERROR( _xlfn.XLOOKUP( TRIM(CLEAN(TEXT(_xlpm.k,"@"))), TRIM(CLEAN(TEXT(kbli!$C$2:$C$1787,"@"))), kbli!$D$2:$D$1787, "" ), "" ) )), _xlfn.TEXTJOIN(" | ", TRUE, _xlpm.hasil) ) ) )}
G3163: {=IFERROR( _xlfn.TEXTJOIN(", ", TRUE, TEXT(TRIM(_xlfn.TEXTAFTER( _xlfn.TEXTBEFORE( _xlfn.FILTERXML("<t><s>" & SUBSTITUTE(D3163, ";", "</s><s>") & "</s></t>", "//s"), "]" ), "KBLI:" )), "00000") ), "")} | H3163: {=IF(G3163="","", _xlfn.TEXTJOIN(", ",TRUE, _xlfn.UNIQUE( _xlfn.MAP( _xlfn.TEXTSPLIT(G3163,","),_xlfn.LAMBDA(_xlpm.k, _xlfn.LET( _xlpm.kode,TRIM(TEXT(_xlpm.k,"00000")), _xlpm.d,--LEFT(_xlpm.kode,2), IF(AND(_xlpm.d>=1,_xlpm.d<=3),"A", IF(AND(_xlpm.d>=5,_xlpm.d<=9),"B", IF(AND(_xlpm.d>=10,_xlpm.d<=33),"C", IF(_xlpm.d=35,"D", IF(AND(_xlpm.d>=36,_xlpm.d<=39),"E", IF(AND(_xlpm.d>=41,_xlpm.d<=43),"F", IF(AND(_xlpm.d>=45,_xlpm.d<=47),"G", IF(AND(_xlpm.d>=49,_xlpm.d<=53),"H", IF(AND(_xlpm.d>=55,_xlpm.d<=56),"I", IF(AND(_xlpm.d>=58,_xlpm.d<=63),"J", IF(AND(_xlpm.d>=64,_xlpm.d<=66),"K", IF(_xlpm.d=68,"L", IF(AND(_xlpm.d>=69,_xlpm.d<=75),"M", IF(AND(_xlpm.d>=77,_xlpm.d<=82),"N", IF(_xlpm.d=84,"O", IF(_xlpm.d=85,"P", IF(AND(_xlpm.d>=86,_xlpm.d<=88),"Q", IF(AND(_xlpm.d>=90,_xlpm.d<=93),"R", IF(AND(_xlpm.d>=94,_xlpm.d<=96),"S", IF(AND(_xlpm.d>=97,_xlpm.d<=98),"T", IF(_xlpm.d=99,"U","Tidak diketahui"))))))))))))))))))))) ) ) ) ) ))} | I3163: {=_xlfn.LET( _xlpm.isi, G3163, IF(_xlpm.isi="","", _xlfn.LET( _xlpm.daftar, _xlfn.TEXTSPLIT(_xlpm.isi, ","), _xlpm.bersih, TRIM(_xlpm.daftar), _xlpm.hasil, _xlfn.MAP(_xlpm.bersih, _xlfn.LAMBDA(_xlpm.k, IFERROR( _xlfn.XLOOKUP( TRIM(CLEAN(TEXT(_xlpm.k,"@"))), TRIM(CLEAN(TEXT(kbli!$C$2:$C$1787,"@"))), kbli!$D$2:$D$1787, "" ), "" ) )), _xlfn.TEXTJOIN(" | ", TRUE, _xlpm.hasil) ) ) )}
G3164: {=IFERROR( _xlfn.TEXTJOIN(", ", TRUE, TEXT(TRIM(_xlfn.TEXTAFTER( _xlfn.TEXTBEFORE( _xlfn.FILTERXML("<t><s>" & SUBSTITUTE(D3164, ";", "</s><s>") & "</s></t>", "//s"), "]" ), "KBLI:" )), "00000") ), "")} | H3164: {=IF(G3164="","", _xlfn.TEXTJOIN(", ",TRUE, _xlfn.UNIQUE( _xlfn.MAP( _xlfn.TEXTSPLIT(G3164,","),_xlfn.LAMBDA(_xlpm.k, _xlfn.LET( _xlpm.kode,TRIM(TEXT(_xlpm.k,"00000")), _xlpm.d,--LEFT(_xlpm.kode,2), IF(AND(_xlpm.d>=1,_xlpm.d<=3),"A", IF(AND(_xlpm.d>=5,_xlpm.d<=9),"B", IF(AND(_xlpm.d>=10,_xlpm.d<=33),"C", IF(_xlpm.d=35,"D", IF(AND(_xlpm.d>=36,_xlpm.d<=39),"E", IF(AND(_xlpm.d>=41,_xlpm.d<=43),"F", IF(AND(_xlpm.d>=45,_xlpm.d<=47),"G", IF(AND(_xlpm.d>=49,_xlpm.d<=53),"H", IF(AND(_xlpm.d>=55,_xlpm.d<=56),"I", IF(AND(_xlpm.d>=58,_xlpm.d<=63),"J", IF(AND(_xlpm.d>=64,_xlpm.d<=66),"K", IF(_xlpm.d=68,"L", IF(AND(_xlpm.d>=69,_xlpm.d<=75),"M", IF(AND(_xlpm.d>=77,_xlpm.d<=82),"N", IF(_xlpm.d=84,"O", IF(_xlpm.d=85,"P", IF(AND(_xlpm.d>=86,_xlpm.d<=88),"Q", IF(AND(_xlpm.d>=90,_xlpm.d<=93),"R", IF(AND(_xlpm.d>=94,_xlpm.d<=96),"S", IF(AND(_xlpm.d>=97,_xlpm.d<=98),"T", IF(_xlpm.d=99,"U","Tidak diketahui"))))))))))))))))))))) ) ) ) ) ))} | I3164: {=_xlfn.LET( _xlpm.isi, G3164, IF(_xlpm.isi="","", _xlfn.LET( _xlpm.daftar, _xlfn.TEXTSPLIT(_xlpm.isi, ","), _xlpm.bersih, TRIM(_xlpm.daftar), _xlpm.hasil, _xlfn.MAP(_xlpm.bersih, _xlfn.LAMBDA(_xlpm.k, IFERROR( _xlfn.XLOOKUP( TRIM(CLEAN(TEXT(_xlpm.k,"@"))), TRIM(CLEAN(TEXT(kbli!$C$2:$C$1787,"@"))), kbli!$D$2:$D$1787, "" ), "" ) )), _xlfn.TEXTJOIN(" | ", TRUE, _xlpm.hasil) ) ) )}
G3165: {=IFERROR( _xlfn.TEXTJOIN(", ", TRUE, TEXT(TRIM(_xlfn.TEXTAFTER( _xlfn.TEXTBEFORE( _xlfn.FILTERXML("<t><s>" & SUBSTITUTE(D3165, ";", "</s><s>") & "</s></t>", "//s"), "]" ), "KBLI:" )), "00000") ), "")} | H3165: {=IF(G3165="","", _xlfn.TEXTJOIN(", ",TRUE, _xlfn.UNIQUE( _xlfn.MAP( _xlfn.TEXTSPLIT(G3165,","),_xlfn.LAMBDA(_xlpm.k, _xlfn.LET( _xlpm.kode,TRIM(TEXT(_xlpm.k,"00000")), _xlpm.d,--LEFT(_xlpm.kode,2), IF(AND(_xlpm.d>=1,_xlpm.d<=3),"A", IF(AND(_xlpm.d>=5,_xlpm.d<=9),"B", IF(AND(_xlpm.d>=10,_xlpm.d<=33),"C", IF(_xlpm.d=35,"D", IF(AND(_xlpm.d>=36,_xlpm.d<=39),"E", IF(AND(_xlpm.d>=41,_xlpm.d<=43),"F", IF(AND(_xlpm.d>=45,_xlpm.d<=47),"G", IF(AND(_xlpm.d>=49,_xlpm.d<=53),"H", IF(AND(_xlpm.d>=55,_xlpm.d<=56),"I", IF(AND(_xlpm.d>=58,_xlpm.d<=63),"J", IF(AND(_xlpm.d>=64,_xlpm.d<=66),"K", IF(_xlpm.d=68,"L", IF(AND(_xlpm.d>=69,_xlpm.d<=75),"M", IF(AND(_xlpm.d>=77,_xlpm.d<=82),"N", IF(_xlpm.d=84,"O", IF(_xlpm.d=85,"P", IF(AND(_xlpm.d>=86,_xlpm.d<=88),"Q", IF(AND(_xlpm.d>=90,_xlpm.d<=93),"R", IF(AND(_xlpm.d>=94,_xlpm.d<=96),"S", IF(AND(_xlpm.d>=97,_xlpm.d<=98),"T", IF(_xlpm.d=99,"U","Tidak diketahui"))))))))))))))))))))) ) ) ) ) ))} | I3165: {=_xlfn.LET( _xlpm.isi, G3165, IF(_xlpm.isi="","", _xlfn.LET( _xlpm.daftar, _xlfn.TEXTSPLIT(_xlpm.isi, ","), _xlpm.bersih, TRIM(_xlpm.daftar), _xlpm.hasil, _xlfn.MAP(_xlpm.bersih, _xlfn.LAMBDA(_xlpm.k, IFERROR( _xlfn.XLOOKUP( TRIM(CLEAN(TEXT(_xlpm.k,"@"))), TRIM(CLEAN(TEXT(kbli!$C$2:$C$1787,"@"))), kbli!$D$2:$D$1787, "" ), "" ) )), _xlfn.TEXTJOIN(" | ", TRUE, _xlpm.hasil) ) ) )}
G3166: {=IFERROR( _xlfn.TEXTJOIN(", ", TRUE, TEXT(TRIM(_xlfn.TEXTAFTER( _xlfn.TEXTBEFORE( _xlfn.FILTERXML("<t><s>" & SUBSTITUTE(D3166, ";", "</s><s>") & "</s></t>", "//s"), "]" ), "KBLI:" )), "00000") ), "")} | H3166: {=IF(G3166="","", _xlfn.TEXTJOIN(", ",TRUE, _xlfn.UNIQUE( _xlfn.MAP( _xlfn.TEXTSPLIT(G3166,","),_xlfn.LAMBDA(_xlpm.k, _xlfn.LET( _xlpm.kode,TRIM(TEXT(_xlpm.k,"00000")), _xlpm.d,--LEFT(_xlpm.kode,2), IF(AND(_xlpm.d>=1,_xlpm.d<=3),"A", IF(AND(_xlpm.d>=5,_xlpm.d<=9),"B", IF(AND(_xlpm.d>=10,_xlpm.d<=33),"C", IF(_xlpm.d=35,"D", IF(AND(_xlpm.d>=36,_xlpm.d<=39),"E", IF(AND(_xlpm.d>=41,_xlpm.d<=43),"F", IF(AND(_xlpm.d>=45,_xlpm.d<=47),"G", IF(AND(_xlpm.d>=49,_xlpm.d<=53),"H", IF(AND(_xlpm.d>=55,_xlpm.d<=56),"I", IF(AND(_xlpm.d>=58,_xlpm.d<=63),"J", IF(AND(_xlpm.d>=64,_xlpm.d<=66),"K", IF(_xlpm.d=68,"L", IF(AND(_xlpm.d>=69,_xlpm.d<=75),"M", IF(AND(_xlpm.d>=77,_xlpm.d<=82),"N", IF(_xlpm.d=84,"O", IF(_xlpm.d=85,"P", IF(AND(_xlpm.d>=86,_xlpm.d<=88),"Q", IF(AND(_xlpm.d>=90,_xlpm.d<=93),"R", IF(AND(_xlpm.d>=94,_xlpm.d<=96),"S", IF(AND(_xlpm.d>=97,_xlpm.d<=98),"T", IF(_xlpm.d=99,"U","Tidak diketahui"))))))))))))))))))))) ) ) ) ) ))} | I3166: {=_xlfn.LET( _xlpm.isi, G3166, IF(_xlpm.isi="","", _xlfn.LET( _xlpm.daftar, _xlfn.TEXTSPLIT(_xlpm.isi, ","), _xlpm.bersih, TRIM(_xlpm.daftar), _xlpm.hasil, _xlfn.MAP(_xlpm.bersih, _xlfn.LAMBDA(_xlpm.k, IFERROR( _xlfn.XLOOKUP( TRIM(CLEAN(TEXT(_xlpm.k,"@"))), TRIM(CLEAN(TEXT(kbli!$C$2:$C$1787,"@"))), kbli!$D$2:$D$1787, "" ), "" ) )), _xlfn.TEXTJOIN(" | ", TRUE, _xlpm.hasil) ) ) )}
G3167: {=IFERROR( _xlfn.TEXTJOIN(", ", TRUE, TEXT(TRIM(_xlfn.TEXTAFTER( _xlfn.TEXTBEFORE( _xlfn.FILTERXML("<t><s>" & SUBSTITUTE(D3167, ";", "</s><s>") & "</s></t>", "//s"), "]" ), "KBLI:" )), "00000") ), "")} | H3167: {=IF(G3167="","", _xlfn.TEXTJOIN(", ",TRUE, _xlfn.UNIQUE( _xlfn.MAP( _xlfn.TEXTSPLIT(G3167,","),_xlfn.LAMBDA(_xlpm.k, _xlfn.LET( _xlpm.kode,TRIM(TEXT(_xlpm.k,"00000")), _xlpm.d,--LEFT(_xlpm.kode,2), IF(AND(_xlpm.d>=1,_xlpm.d<=3),"A", IF(AND(_xlpm.d>=5,_xlpm.d<=9),"B", IF(AND(_xlpm.d>=10,_xlpm.d<=33),"C", IF(_xlpm.d=35,"D", IF(AND(_xlpm.d>=36,_xlpm.d<=39),"E", IF(AND(_xlpm.d>=41,_xlpm.d<=43),"F", IF(AND(_xlpm.d>=45,_xlpm.d<=47),"G", IF(AND(_xlpm.d>=49,_xlpm.d<=53),"H", IF(AND(_xlpm.d>=55,_xlpm.d<=56),"I", IF(AND(_xlpm.d>=58,_xlpm.d<=63),"J", IF(AND(_xlpm.d>=64,_xlpm.d<=66),"K", IF(_xlpm.d=68,"L", IF(AND(_xlpm.d>=69,_xlpm.d<=75),"M", IF(AND(_xlpm.d>=77,_xlpm.d<=82),"N", IF(_xlpm.d=84,"O", IF(_xlpm.d=85,"P", IF(AND(_xlpm.d>=86,_xlpm.d<=88),"Q", IF(AND(_xlpm.d>=90,_xlpm.d<=93),"R", IF(AND(_xlpm.d>=94,_xlpm.d<=96),"S", IF(AND(_xlpm.d>=97,_xlpm.d<=98),"T", IF(_xlpm.d=99,"U","Tidak diketahui"))))))))))))))))))))) ) ) ) ) ))} | I3167: {=_xlfn.LET( _xlpm.isi, G3167, IF(_xlpm.isi="","", _xlfn.LET( _xlpm.daftar, _xlfn.TEXTSPLIT(_xlpm.isi, ","), _xlpm.bersih, TRIM(_xlpm.daftar), _xlpm.hasil, _xlfn.MAP(_xlpm.bersih, _xlfn.LAMBDA(_xlpm.k, IFERROR( _xlfn.XLOOKUP( TRIM(CLEAN(TEXT(_xlpm.k,"@"))), TRIM(CLEAN(TEXT(kbli!$C$2:$C$1787,"@"))), kbli!$D$2:$D$1787, "" ), "" ) )), _xlfn.TEXTJOIN(" | ", TRUE, _xlpm.hasil) ) ) )}
G3168: {=IFERROR( _xlfn.TEXTJOIN(", ", TRUE, TEXT(TRIM(_xlfn.TEXTAFTER( _xlfn.TEXTBEFORE( _xlfn.FILTERXML("<t><s>" & SUBSTITUTE(D3168, ";", "</s><s>") & "</s></t>", "//s"), "]" ), "KBLI:" )), "00000") ), "")} | H3168: {=IF(G3168="","", _xlfn.TEXTJOIN(", ",TRUE, _xlfn.UNIQUE( _xlfn.MAP( _xlfn.TEXTSPLIT(G3168,","),_xlfn.LAMBDA(_xlpm.k, _xlfn.LET( _xlpm.kode,TRIM(TEXT(_xlpm.k,"00000")), _xlpm.d,--LEFT(_xlpm.kode,2), IF(AND(_xlpm.d>=1,_xlpm.d<=3),"A", IF(AND(_xlpm.d>=5,_xlpm.d<=9),"B", IF(AND(_xlpm.d>=10,_xlpm.d<=33),"C", IF(_xlpm.d=35,"D", IF(AND(_xlpm.d>=36,_xlpm.d<=39),"E", IF(AND(_xlpm.d>=41,_xlpm.d<=43),"F", IF(AND(_xlpm.d>=45,_xlpm.d<=47),"G", IF(AND(_xlpm.d>=49,_xlpm.d<=53),"H", IF(AND(_xlpm.d>=55,_xlpm.d<=56),"I", IF(AND(_xlpm.d>=58,_xlpm.d<=63),"J", IF(AND(_xlpm.d>=64,_xlpm.d<=66),"K", IF(_xlpm.d=68,"L", IF(AND(_xlpm.d>=69,_xlpm.d<=75),"M", IF(AND(_xlpm.d>=77,_xlpm.d<=82),"N", IF(_xlpm.d=84,"O", IF(_xlpm.d=85,"P", IF(AND(_xlpm.d>=86,_xlpm.d<=88),"Q", IF(AND(_xlpm.d>=90,_xlpm.d<=93),"R", IF(AND(_xlpm.d>=94,_xlpm.d<=96),"S", IF(AND(_xlpm.d>=97,_xlpm.d<=98),"T", IF(_xlpm.d=99,"U","Tidak diketahui"))))))))))))))))))))) ) ) ) ) ))} | I3168: {=_xlfn.LET( _xlpm.isi, G3168, IF(_xlpm.isi="","", _xlfn.LET( _xlpm.daftar, _xlfn.TEXTSPLIT(_xlpm.isi, ","), _xlpm.bersih, TRIM(_xlpm.daftar), _xlpm.hasil, _xlfn.MAP(_xlpm.bersih, _xlfn.LAMBDA(_xlpm.k, IFERROR( _xlfn.XLOOKUP( TRIM(CLEAN(TEXT(_xlpm.k,"@"))), TRIM(CLEAN(TEXT(kbli!$C$2:$C$1787,"@"))), kbli!$D$2:$D$1787, "" ), "" ) )), _xlfn.TEXTJOIN(" | ", TRUE, _xlpm.hasil) ) ) )}
G3169: {=IFERROR( _xlfn.TEXTJOIN(", ", TRUE, TEXT(TRIM(_xlfn.TEXTAFTER( _xlfn.TEXTBEFORE( _xlfn.FILTERXML("<t><s>" & SUBSTITUTE(D3169, ";", "</s><s>") & "</s></t>", "//s"), "]" ), "KBLI:" )), "00000") ), "")} | H3169: {=IF(G3169="","", _xlfn.TEXTJOIN(", ",TRUE, _xlfn.UNIQUE( _xlfn.MAP( _xlfn.TEXTSPLIT(G3169,","),_xlfn.LAMBDA(_xlpm.k, _xlfn.LET( _xlpm.kode,TRIM(TEXT(_xlpm.k,"00000")), _xlpm.d,--LEFT(_xlpm.kode,2), IF(AND(_xlpm.d>=1,_xlpm.d<=3),"A", IF(AND(_xlpm.d>=5,_xlpm.d<=9),"B", IF(AND(_xlpm.d>=10,_xlpm.d<=33),"C", IF(_xlpm.d=35,"D", IF(AND(_xlpm.d>=36,_xlpm.d<=39),"E", IF(AND(_xlpm.d>=41,_xlpm.d<=43),"F", IF(AND(_xlpm.d>=45,_xlpm.d<=47),"G", IF(AND(_xlpm.d>=49,_xlpm.d<=53),"H", IF(AND(_xlpm.d>=55,_xlpm.d<=56),"I", IF(AND(_xlpm.d>=58,_xlpm.d<=63),"J", IF(AND(_xlpm.d>=64,_xlpm.d<=66),"K", IF(_xlpm.d=68,"L", IF(AND(_xlpm.d>=69,_xlpm.d<=75),"M", IF(AND(_xlpm.d>=77,_xlpm.d<=82),"N", IF(_xlpm.d=84,"O", IF(_xlpm.d=85,"P", IF(AND(_xlpm.d>=86,_xlpm.d<=88),"Q", IF(AND(_xlpm.d>=90,_xlpm.d<=93),"R", IF(AND(_xlpm.d>=94,_xlpm.d<=96),"S", IF(AND(_xlpm.d>=97,_xlpm.d<=98),"T", IF(_xlpm.d=99,"U","Tidak diketahui"))))))))))))))))))))) ) ) ) ) ))} | I3169: {=_xlfn.LET( _xlpm.isi, G3169, IF(_xlpm.isi="","", _xlfn.LET( _xlpm.daftar, _xlfn.TEXTSPLIT(_xlpm.isi, ","), _xlpm.bersih, TRIM(_xlpm.daftar), _xlpm.hasil, _xlfn.MAP(_xlpm.bersih, _xlfn.LAMBDA(_xlpm.k, IFERROR( _xlfn.XLOOKUP( TRIM(CLEAN(TEXT(_xlpm.k,"@"))), TRIM(CLEAN(TEXT(kbli!$C$2:$C$1787,"@"))), kbli!$D$2:$D$1787, "" ), "" ) )), _xlfn.TEXTJOIN(" | ", TRUE, _xlpm.hasil) ) ) )}
G3170: {=IFERROR( _xlfn.TEXTJOIN(", ", TRUE, TEXT(TRIM(_xlfn.TEXTAFTER( _xlfn.TEXTBEFORE( _xlfn.FILTERXML("<t><s>" & SUBSTITUTE(D3170, ";", "</s><s>") & "</s></t>", "//s"), "]" ), "KBLI:" )), "00000") ), "")} | H3170: {=IF(G3170="","", _xlfn.TEXTJOIN(", ",TRUE, _xlfn.UNIQUE( _xlfn.MAP( _xlfn.TEXTSPLIT(G3170,","),_xlfn.LAMBDA(_xlpm.k, _xlfn.LET( _xlpm.kode,TRIM(TEXT(_xlpm.k,"00000")), _xlpm.d,--LEFT(_xlpm.kode,2), IF(AND(_xlpm.d>=1,_xlpm.d<=3),"A", IF(AND(_xlpm.d>=5,_xlpm.d<=9),"B", IF(AND(_xlpm.d>=10,_xlpm.d<=33),"C", IF(_xlpm.d=35,"D", IF(AND(_xlpm.d>=36,_xlpm.d<=39),"E", IF(AND(_xlpm.d>=41,_xlpm.d<=43),"F", IF(AND(_xlpm.d>=45,_xlpm.d<=47),"G", IF(AND(_xlpm.d>=49,_xlpm.d<=53),"H", IF(AND(_xlpm.d>=55,_xlpm.d<=56),"I", IF(AND(_xlpm.d>=58,_xlpm.d<=63),"J", IF(AND(_xlpm.d>=64,_xlpm.d<=66),"K", IF(_xlpm.d=68,"L", IF(AND(_xlpm.d>=69,_xlpm.d<=75),"M", IF(AND(_xlpm.d>=77,_xlpm.d<=82),"N", IF(_xlpm.d=84,"O", IF(_xlpm.d=85,"P", IF(AND(_xlpm.d>=86,_xlpm.d<=88),"Q", IF(AND(_xlpm.d>=90,_xlpm.d<=93),"R", IF(AND(_xlpm.d>=94,_xlpm.d<=96),"S", IF(AND(_xlpm.d>=97,_xlpm.d<=98),"T", IF(_xlpm.d=99,"U","Tidak diketahui"))))))))))))))))))))) ) ) ) ) ))} | I3170: {=_xlfn.LET( _xlpm.isi, G3170, IF(_xlpm.isi="","", _xlfn.LET( _xlpm.daftar, _xlfn.TEXTSPLIT(_xlpm.isi, ","), _xlpm.bersih, TRIM(_xlpm.daftar), _xlpm.hasil, _xlfn.MAP(_xlpm.bersih, _xlfn.LAMBDA(_xlpm.k, IFERROR( _xlfn.XLOOKUP( TRIM(CLEAN(TEXT(_xlpm.k,"@"))), TRIM(CLEAN(TEXT(kbli!$C$2:$C$1787,"@"))), kbli!$D$2:$D$1787, "" ), "" ) )), _xlfn.TEXTJOIN(" | ", TRUE, _xlpm.hasil) ) ) )}
G3171: {=IFERROR( _xlfn.TEXTJOIN(", ", TRUE, TEXT(TRIM(_xlfn.TEXTAFTER( _xlfn.TEXTBEFORE( _xlfn.FILTERXML("<t><s>" & SUBSTITUTE(D3171, ";", "</s><s>") & "</s></t>", "//s"), "]" ), "KBLI:" )), "00000") ), "")} | H3171: {=IF(G3171="","", _xlfn.TEXTJOIN(", ",TRUE, _xlfn.UNIQUE( _xlfn.MAP( _xlfn.TEXTSPLIT(G3171,","),_xlfn.LAMBDA(_xlpm.k, _xlfn.LET( _xlpm.kode,TRIM(TEXT(_xlpm.k,"00000")), _xlpm.d,--LEFT(_xlpm.kode,2), IF(AND(_xlpm.d>=1,_xlpm.d<=3),"A", IF(AND(_xlpm.d>=5,_xlpm.d<=9),"B", IF(AND(_xlpm.d>=10,_xlpm.d<=33),"C", IF(_xlpm.d=35,"D", IF(AND(_xlpm.d>=36,_xlpm.d<=39),"E", IF(AND(_xlpm.d>=41,_xlpm.d<=43),"F", IF(AND(_xlpm.d>=45,_xlpm.d<=47),"G", IF(AND(_xlpm.d>=49,_xlpm.d<=53),"H", IF(AND(_xlpm.d>=55,_xlpm.d<=56),"I", IF(AND(_xlpm.d>=58,_xlpm.d<=63),"J", IF(AND(_xlpm.d>=64,_xlpm.d<=66),"K", IF(_xlpm.d=68,"L", IF(AND(_xlpm.d>=69,_xlpm.d<=75),"M", IF(AND(_xlpm.d>=77,_xlpm.d<=82),"N", IF(_xlpm.d=84,"O", IF(_xlpm.d=85,"P", IF(AND(_xlpm.d>=86,_xlpm.d<=88),"Q", IF(AND(_xlpm.d>=90,_xlpm.d<=93),"R", IF(AND(_xlpm.d>=94,_xlpm.d<=96),"S", IF(AND(_xlpm.d>=97,_xlpm.d<=98),"T", IF(_xlpm.d=99,"U","Tidak diketahui"))))))))))))))))))))) ) ) ) ) ))} | I3171: {=_xlfn.LET( _xlpm.isi, G3171, IF(_xlpm.isi="","", _xlfn.LET( _xlpm.daftar, _xlfn.TEXTSPLIT(_xlpm.isi, ","), _xlpm.bersih, TRIM(_xlpm.daftar), _xlpm.hasil, _xlfn.MAP(_xlpm.bersih, _xlfn.LAMBDA(_xlpm.k, IFERROR( _xlfn.XLOOKUP( TRIM(CLEAN(TEXT(_xlpm.k,"@"))), TRIM(CLEAN(TEXT(kbli!$C$2:$C$1787,"@"))), kbli!$D$2:$D$1787, "" ), "" ) )), _xlfn.TEXTJOIN(" | ", TRUE, _xlpm.hasil) ) ) )}
... G7572: {=IFERROR( _xlfn.TEXTJOIN(", ", TRUE, TEXT(TRIM(_xlfn.TEXTAFTER( _xlfn.TEXTBEFORE( _xlfn.FILTERXML("<t><s>" & SUBSTITUTE(D7572, ";", "</s><s>") & "</s></t>", "//s"), "]" ), "KBLI:" )), "00000") ), "")} | H7572: {=IF(G7572="","", _xlfn.TEXTJOIN(", ",TRUE, _xlfn.UNIQUE( _xlfn.MAP( _xlfn.TEXTSPLIT(G7572,","),_xlfn.LAMBDA(_xlpm.k, _xlfn.LET( _xlpm.kode,TRIM(TEXT(_xlpm.k,"00000")), _xlpm.d,--LEFT(_xlpm.kode,2), IF(AND(_xlpm.d>=1,_xlpm.d<=3),"A", IF(AND(_xlpm.d>=5,_xlpm.d<=9),"B", IF(AND(_xlpm.d>=10,_xlpm.d<=33),"C", IF(_xlpm.d=35,"D", IF(AND(_xlpm.d>=36,_xlpm.d<=39),"E", IF(AND(_xlpm.d>=41,_xlpm.d<=43),"F", IF(AND(_xlpm.d>=45,_xlpm.d<=47),"G", IF(AND(_xlpm.d>=49,_xlpm.d<=53),"H", IF(AND(_xlpm.d>=55,_xlpm.d<=56),"I", IF(AND(_xlpm.d>=58,_xlpm.d<=63),"J", IF(AND(_xlpm.d>=64,_xlpm.d<=66),"K", IF(_xlpm.d=68,"L", IF(AND(_xlpm.d>=69,_xlpm.d<=75),"M", IF(AND(_xlpm.d>=77,_xlpm.d<=82),"N", IF(_xlpm.d=84,"O", IF(_xlpm.d=85,"P", IF(AND(_xlpm.d>=86,_xlpm.d<=88),"Q", IF(AND(_xlpm.d>=90,_xlpm.d<=93),"R", IF(AND(_xlpm.d>=94,_xlpm.d<=96),"S", IF(AND(_xlpm.d>=97,_xlpm.d<=98),"T", IF(_xlpm.d=99,"U","Tidak diketahui"))))))))))))))))))))) ) ) ) ) ))} | I7572: {=_xlfn.LET( _xlpm.isi, G7572, IF(_xlpm.isi="","", _xlfn.LET( _xlpm.daftar, _xlfn.TEXTSPLIT(_xlpm.isi, ","), _xlpm.bersih, TRIM(_xlpm.daftar), _xlpm.hasil, _xlfn.MAP(_xlpm.bersih, _xlfn.LAMBDA(_xlpm.k, IFERROR( _xlfn.XLOOKUP( TRIM(CLEAN(TEXT(_xlpm.k,"@"))), TRIM(CLEAN(TEXT(kbli!$C$2:$C$1787,"@"))), kbli!$D$2:$D$1787, "" ), "" ) )), _xlfn.TEXTJOIN(" | ", TRUE, _xlpm.hasil) ) ) )}

Sheet kbli
A1: id | B1: kategori_kbli | C1: kode_kbli | D1: kelompok_kbli | E1: aktivitas_perusahaan | F1: kbli_code
A2: 1 | B2: =_xlfn.LET( _xlpm.kode, TRIM(TEXT(C2,"00000")), _xlpm.d, --LEFT(_xlpm.kode,2), IF(AND(_xlpm.d>=1, _xlpm.d<=3),"A", IF(AND(_xlpm.d>=5, _xlpm.d<=9),"B", IF(AND(_xlpm.d>=10, _xlpm.d<=33),"C", IF(_xlpm.d=35,"D", IF(AND(_xlpm.d>=36, _xlpm.d<=39),"E", IF(AND(_xlpm.d>=41, _xlpm.d<=43),"F", IF(AND(_xlpm.d>=45, _xlpm.d<=47),"G", IF(AND(_xlpm.d>=49, _xlpm.d<=53),"H", IF(AND(_xlpm.d>=55, _xlpm.d<=56),"I", IF(AND(_xlpm.d>=58, _xlpm.d<=63),"J", IF(AND(_xlpm.d>=64, _xlpm.d<=66),"K", IF(_xlpm.d=68,"L", IF(AND(_xlpm.d>=69, _xlpm.d<=75),"M", IF(AND(_xlpm.d>=77, _xlpm.d<=82),"N", IF(_xlpm.d=84,"O", IF(_xlpm.d=85,"P", IF(AND(_xlpm.d>=86, _xlpm.d<=88),"Q", IF(AND(_xlpm.d>=90, _xlpm.d<=93),"R", IF(AND(_xlpm.d>=94, _xlpm.d<=96),"S", IF(AND(_xlpm.d>=97, _xlpm.d<=98),"T", IF(_xlpm.d=99,"U","Tidak diketahui"))))))))))))))))))))) ) -> A | C2: 01111 | D2: Pertanian Jagung | E2: Kelompok ini mencakup usaha pertanian komoditas jagung mulai dari kegiatan pengolahan lahan, penanaman, pemeliharaan, dan juga pemanenan dan pasca panen jika menjadi satu kesatuan kegiatan tanaman jagung. Termasuk kegiatan pembibitan dan pembenihan tanaman jagung. | F2: kbli_01111
A3: 2 | B3: =_xlfn.LET( _xlpm.kode, TRIM(TEXT(C3,"00000")), _xlpm.d, --LEFT(_xlpm.kode,2), IF(AND(_xlpm.d>=1, _xlpm.d<=3),"A", IF(AND(_xlpm.d>=5, _xlpm.d<=9),"B", IF(AND(_xlpm.d>=10, _xlpm.d<=33),"C", IF(_xlpm.d=35,"D", IF(AND(_xlpm.d>=36, _xlpm.d<=39),"E", IF(AND(_xlpm.d>=41, _xlpm.d<=43),"F", IF(AND(_xlpm.d>=45, _xlpm.d<=47),"G", IF(AND(_xlpm.d>=49, _xlpm.d<=53),"H", IF(AND(_xlpm.d>=55, _xlpm.d<=56),"I", IF(AND(_xlpm.d>=58, _xlpm.d<=63),"J", IF(AND(_xlpm.d>=64, _xlpm.d<=66),"K", IF(_xlpm.d=68,"L", IF(AND(_xlpm.d>=69, _xlpm.d<=75),"M", IF(AND(_xlpm.d>=77, _xlpm.d<=82),"N", IF(_xlpm.d=84,"O", IF(_xlpm.d=85,"P", IF(AND(_xlpm.d>=86, _xlpm.d<=88),"Q", IF(AND(_xlpm.d>=90, _xlpm.d<=93),"R", IF(AND(_xlpm.d>=94, _xlpm.d<=96),"S", IF(AND(_xlpm.d>=97, _xlpm.d<=98),"T", IF(_xlpm.d=99,"U","Tidak diketahui"))))))))))))))))))))) ) -> A | C3: 01112 | D3: Pertanian Gandum | E3: Kelompok ini mencakup usaha pertanian gandum mulai dari kegiatan pengolahan lahan, penanaman, pemeliharaan, dan juga pemanenan dan pasca panen jika menjadi satu kesatuan kegiatan tanaman serealia gandum, seperti sorgum/cantel, gandum (wheat/oats), jelai (barley), gandum hitam (rye), jawawut (millet) dan sejenisnya. Termasuk kegiatan pembibitan dan pembenihan tanaman gandum. | F3: kbli_01112
A4: 3 | B4: =_xlfn.LET( _xlpm.kode, TRIM(TEXT(C4,"00000")), _xlpm.d, --LEFT(_xlpm.kode,2), IF(AND(_xlpm.d>=1, _xlpm.d<=3),"A", IF(AND(_xlpm.d>=5, _xlpm.d<=9),"B", IF(AND(_xlpm.d>=10, _xlpm.d<=33),"C", IF(_xlpm.d=35,"D", IF(AND(_xlpm.d>=36, _xlpm.d<=39),"E", IF(AND(_xlpm.d>=41, _xlpm.d<=43),"F", IF(AND(_xlpm.d>=45, _xlpm.d<=47),"G", IF(AND(_xlpm.d>=49, _xlpm.d<=53),"H", IF(AND(_xlpm.d>=55, _xlpm.d<=56),"I", IF(AND(_xlpm.d>=58, _xlpm.d<=63),"J", IF(AND(_xlpm.d>=64, _xlpm.d<=66),"K", IF(_xlpm.d=68,"L", IF(AND(_xlpm.d>=69, _xlpm.d<=75),"M", IF(AND(_xlpm.d>=77, _xlpm.d<=82),"N", IF(_xlpm.d=84,"O", IF(_xlpm.d=85,"P", IF(AND(_xlpm.d>=86, _xlpm.d<=88),"Q", IF(AND(_xlpm.d>=90, _xlpm.d<=93),"R", IF(AND(_xlpm.d>=94, _xlpm.d<=96),"S", IF(AND(_xlpm.d>=97, _xlpm.d<=98),"T", IF(_xlpm.d=99,"U","Tidak diketahui"))))))))))))))))))))) ) -> A | C4: 01113 | D4: Pertanian Kedelai | E4: Kelompok ini mencakup usaha pertanian kedelai mulai dari kegiatan pengolahan lahan, penanaman, pemeliharaan, dan juga pemanenan dan pasca panen jika menjadi satu kesatuan kegiatan tanaman kedelai (kacang palawija). Termasuk kegiatan pembibitan dan pembenihan tanaman kedelai. | F4: kbli_01113
A5: 4 | B5: =_xlfn.LET( _xlpm.kode, TRIM(TEXT(C5,"00000")), _xlpm.d, --LEFT(_xlpm.kode,2), IF(AND(_xlpm.d>=1, _xlpm.d<=3),"A", IF(AND(_xlpm.d>=5, _xlpm.d<=9),"B", IF(AND(_xlpm.d>=10, _xlpm.d<=33),"C", IF(_xlpm.d=35,"D", IF(AND(_xlpm.d>=36, _xlpm.d<=39),"E", IF(AND(_xlpm.d>=41, _xlpm.d<=43),"F", IF(AND(_xlpm.d>=45, _xlpm.d<=47),"G", IF(AND(_xlpm.d>=49, _xlpm.d<=53),"H", IF(AND(_xlpm.d>=55, _xlpm.d<=56),"I", IF(AND(_xlpm.d>=58, _xlpm.d<=63),"J", IF(AND(_xlpm.d>=64, _xlpm.d<=66),"K", IF(_xlpm.d=68,"L", IF(AND(_xlpm.d>=69, _xlpm.d<=75),"M", IF(AND(_xlpm.d>=77, _xlpm.d<=82),"N", IF(_xlpm.d=84,"O", IF(_xlpm.d=85,"P", IF(AND(_xlpm.d>=86, _xlpm.d<=88),"Q", IF(AND(_xlpm.d>=90, _xlpm.d<=93),"R", IF(AND(_xlpm.d>=94, _xlpm.d<=96),"S", IF(AND(_xlpm.d>=97, _xlpm.d<=98),"T", IF(_xlpm.d=99,"U","Tidak diketahui"))))))))))))))))))))) ) -> A | C5: 01114 | D5: Pertanian Kacang Tanah | E5: Kelompok ini mencakup usaha pertanian kacang tanah mulai dari kegiatan pengolahan lahan, penanaman, pemeliharaan, dan juga pemanenan dan pasca panen jika menjadi satu kesatuan kegiatan tanaman kacang tanah (kacang palawija). Termasuk kegiatan pembibitan dan pembenihan tanaman kacang tanah. | F5: kbli_01114
